Workbook

Sheet Daily Sale 
A1: SR# | B1: Item Name | C1: Date | D1: Time | E1: Total Head Count | F1: Rate | G1: Amount | I1: SR# | J1: Item Name | K1: Date | L1: Time | M1: Total Head Count | N1: Rate | O1: Amount
A2: 1 | B2: Chay | C2: 16/12/2025 | D2: Midnight | E2: =G2/F2 -> 194.28571 | F2: 35 | G2: 6800 | I2: 1 | J2: Chay | K2: 17/12/2025 | L2: Midnight | M2: 205 | N2: 35 | O2: =N2*M2 -> 7175
A3: 2 | B3: Paratha | C3: 16/12/2025 | D3: Breakfast | E3: 661 | F3: 35 | G3: =F3*E3 -> 23135 | I3: 2 | J3: Paratha | K3: 17/12/2025 | L3: Breakfast | M3: 700 | N3: 35 | O3: =N3*M3 -> 24500
A4: 3 | B4: Cahanna | C4: 16/12/2025 | D4: Breakfast | E4: 79 | F4: 80 | G4: =F4*E4 -> 6320 | I4: 3 | J4: Allo Ghotala | K4: 17/12/2025 | L4: Breakfast | M4: 85 | N4: 70 | O4: =N4*M4 -> 5950
A5: 4 | B5: Chay | C5: 16/12/2025 | D5: Breakfast | E5: =423+14 -> 437 | F5: 35 | G5: =F5*E5 -> 15295 | I5: 4 | J5: Chay | K5: 17/12/2025 | L5: Breakfast | M5: 450 | N5: 35 | O5: =N5*M5 -> 15750
A6: 5 | B6: Dall | C6: 16/12/2025 | D6: Lunch | E6: 327 | F6: 80 | G6: =F6*E6 -> 26160 | I6: 5 | J6: Sabzi | K6: 17/12/2025 | L6: Lunch | M6: 200 | N6: 80 | O6: =N6*M6 -> 16000
A7: 6 | B7: Rice | C7: 16/12/2025 | D7: Lunch | E7: 31 | F7: 100 | G7: =F7*E7 -> 3100 | I7: 6 | J7: Chicken Qorma | K7: 17/12/2025 | L7: Lunch | M7: 25 | N7: 200 | O7: =N7*M7 -> 5000
A8: 7 | B8: Chicken Karahi | C8: 16/12/2025 | D8: Lunch | E8: 6 | F8: 200 | G8: =F8*E8 -> 1200 | I8: 7 | J8: Chicken curry | K8: 17/12/2025 | L8: Lunch | M8: 250 | N8: 110 | O8: =N8*M8 -> 27500
A9: 8 | B9: Roti | C9: 16/12/2025 | D9: Lunch | E9: 1504 | F9: 15 | G9: =F9*E9 -> 22560 | I9: 8 | J9: Roti | K9: 17/12/2025 | L9: Lunch | M9: 2000 | N9: 15 | O9: =N9*M9 -> 30000
A10: 9 | B10: Chay | C10: 16/12/2025 | D10: Lunch | E10: 128 | F10: 35 | G10: =F10*E10 -> 4480 | I10: 9 | J10: Chay | K10: 17/12/2025 | L10: Lunch | M10: 200 | N10: 35 | O10: =N10*M10 -> 7000
A11: 10 | B11: Chay | C11: 16/12/2025 | D11: Afternoon | E11: 399 | F11: 35 | G11: =F11*E11 -> 13965 | I11: 10 | J11: Chay | K11: 17/12/2025 | L11: Afternoon | M11: 504 | N11: 35 | O11: =N11*M11 -> 17640
A12: 11 | B12: Sabzi | C12: 16/12/2025 | D12: Dinner | E12: 95 | F12: 80 | G12: =F12*E12 -> 7600 | I12: 11 | J12: Sabzi | K12: 17/12/2025 | L12: Dinner | M12: 100 | N12: 80 | O12: =N12*M12 -> 8000
A13: 12 | B13: Roti | C13: 16/12/2025 | D13: Dinner | E13: 651 | F13: 15 | G13: =F13*E13 -> 9765 | I13: 12 | J13: Roti | K13: 17/12/2025 | L13: Dinner | M13: 800 | N13: 15 | O13: =N13*M13 -> 12000
A14: 13 | B14: Chay | C14: 16/12/2025 | D14: Dinner | E14: 33.428571 | F14: 35 | G14: =F14*E14 -> 1170 | I14: 13 | J14: Chay | K14: 17/12/2025 | L14: Dinner | M14: 150 | N14: 35 | O14: =N14*M14 -> 5250
A15: Cash From Sale for tuck Shop | G15: =280+150 -> 430 | I15: Cash From Sale for tuck Shop | O15: =70+120+80+180 -> 450
A16: Total Cash In Hand Amount | G16: =SUM(G2:G14)-G15 -> 141120 | I16: TOTAL AMOUNT OF KITCHN | O16: =SUM(O2:O14)-O15 -> 181315
I17: 1 | J17: Channa Chat | K17: 17/12/2025 | L17: All Day | M17: 130 | N17: 120 | O17: =N17*M17 -> 15600
A18: CREDIT AMOUNT | I18: 2 | J18: Juice | K18: 17/12/2025 | L18: All Day | M18: 110 | N18: 150 | O18: =N18*M18 -> 16500
A19: SR# | B19: Department Name | C19: Date | D19: Time | E19: Amount | G19: G.Total | I19: TOTAL AMOUNT OF JUICE COUNTER | O19: =SUM(O17:O18) -> 32100
A20: 1 | B20: Steaching Deprt | C20: 16/12/2025 | D20: Breakfast, Lunch, Dinner | E20: 5480 | G20: =E20 -> 5480 | I20: Total Cash In Hand Amount | O20: =O16+O19 -> 213415
A21: 2 | B21: Dying | C21: 16/12/2025 | D21: Lunch, | E21: 345 | G21: =E21 -> 345 | I21: CREDIT AMOUNT
A22: 3 | B22: Admin | C22: 16/12/2025 | D22: Lunch | E22: 1125 | G22: =E22 -> 1125 | I22: SR# | J22: Department Name | K22: Date | L22: Time | M22: Amount | O22: G.Total
A23: 4 | B23: Printing | C23: 16/12/2025 | D23: Lunch | E23: 885 | G23: =E23 -> 885 | I23: 1 | J23: Dying | K23: 17/12/2025 | L23: Lunch | M23: 335 | O23: =M23 -> 335
A24: 5 | B24: Sampl | C24: 16/12/2025 | D24: Lunch | E24: 2090 | G24: =E24 -> 2090 | I24: 2 | J24: Admin | K24: 17/12/2025 | L24: Breakfast, Lunch | M24: 1520 | O24: =M24 -> 1520
A25: 6 | B25: Flow HCM | C25: 16/12/2025 | D25: Lunch | E25: 405 | G25: =E25 -> 405 | I25: 3 | J25: Senior Mess | K25: 17/12/2025 | L25: Lunch | M25: 1905 | O25: =M25 -> 1905
A26: 7 | B26: Senior Mess | C26: 16/12/2025 | D26: Lunch, Dinner | E26: 2090 | G26: =E26 -> 2090 | I26: 4 | J26: HR | K26: 17/12/2025 | L26: Lunch | M26: 1190 | O26: =M26 -> 1190
A27: TOTAL AMOUNT | G27: =SUM(G20:G26) -> 12420 | I27: TOTAL AMOUNT | O27: =SUM(O23:O26) -> 4950
A28: GRAND TOTAL AMOUNT | G28: =G16+G27 -> 153540 | I28: GRAND TOTAL AMOUNT | O28: =O20+O27 -> 218365
I30: SR# | J30: Item Name | K30: Date | L30: Time | M30: Total Head Count | N30: Rate | O30: Amount
I31: 1 | J31: Chay | K31: 19/12/2025 | L31: Midnight | M31: 189.42857 | N31: 35 | O31: =N31*M31 -> 6630
I32: 2 | J32: Paratha | K32: 19/12/2025 | L32: Breakfast | M32: 496 | N32: 35 | O32: =N32*M32 -> 17360
A33: SR# | B33: Item Name | C33: Date | D33: Time | E33: Total Head Count | F33: Rate | G33: Amount | I33: 3 | J33: Chana | K33: 19/12/2025 | L33: Breakfast | M33: 7 | N33: 80 | O33: =N33*M33 -> 560
A34: 1 | B34: Chay | C34: 18/12/2025 | D34: Midnight | E34: 182.57 | F34: 35 | G34: =F34*E34 -> 6389.95 | I34: 4 | J34: Chay | K34: 19/12/2025 | L34: Breakfast | M34: 385 | N34: 35 | O34: =N34*M34 -> 13475
A35: 2 | B35: Paratha | C35: 18/12/2025 | D35: Breakfast | E35: 412 | F35: 35 | G35: =F35*E35 -> 14420 | I35: 5 | J35: Dall | K35: 19/12/2025 | L35: Lunch | M35: 40 | N35: 80 | O35: =N35*M35 -> 3200
A36: 3 | B36: Anda Ghotala | C36: 18/12/2025 | D36: Breakfast | E36: 48 | F36: 70 | G36: =F36*E36 -> 3360 | I36: 6 | J36: Chay | K36: 19/12/2025 | L36: Lunch | M36: 99.42857 | N36: 35 | O36: =N36*M36 -> 3479.9999
A37: 4 | B37: Chay | C37: 18/12/2025 | D37: Breakfast | E37: 469 | F37: 35 | G37: =F37*E37 -> 16415 | I37: 7 | J37: Chicken Biryani | K37: 19/12/2025 | L37: Lunch | M37: 590 | N37: 180 | O37: =N37*M37 -> 106200
A38: 5 | B38: Pulao | C38: 18/12/2025 | D38: Lunch | E38: 91 | F38: 120 | G38: =F38*E38 -> 10920 | I38: 8 | J38: Roti | K38: 19/12/2025 | L38: Lunch | M38: 580 | N38: 15 | O38: =N38*M38 -> 8700
A39: 6 | B39: Anda Ghotala | C39: 18/12/2025 | D39: Lunch | E39: 38 | F39: 70 | G39: =F39*E39 -> 2660 | I39: 9 | J39: Chay | K39: 19/12/2025 | L39: Afternoon | M39: 343.71429 | N39: 35 | O39: =N39*M39 -> 12030
A40: 7 | B40: Dall | C40: 18/12/2025 | D40: Lunch | E40: 158 | F40: 80 | G40: =F40*E40 -> 12640 | I40: 10 | J40: Dall | K40: 19/12/2025 | L40: Dinner | M40: 39 | N40: 80 | O40: =N40*M40 -> 3120
A41: 8 | B41: Chay | C41: 18/12/2025 | D41: Lunch | E41: 136 | F41: 35 | G41: =F41*E41 -> 4760 | I41: 11 | J41: Pulao | K41: 19/12/2025 | L41: Dinner | M41: 66 | N41: 120 | O41: =N41*M41 -> 7920
...

Sheet Cash Out From Sale
A1: Cash From Sale
A2: SR# | B2: Name | C2: Amount
A3: 1 | B3: Sadi Bhai For Purcahse | C3: 100000
A4: 2 | B4: Vijay Room Boy | C4: 3500
A5: 3 | B5: Youget | C5: 2560
A6: 4 | B6: Darshan Pay 1000+500 | C6: 1500
A7: 5 | B7: Milk Payment | C7: 14300
A8: 6 | B8: Cook Satalment | C8: 25666
A9: 7 | B9: Sadi Bhai For Purcahse | C9: 8050
A10: 8 | B10: Sadi Bhai For Purcahse | C10: 5000
A11: 9 | B11: Ashiq Hussain Advance | C11: 3000
A12: 10 | B12: Sadi Bhai For Purcahse | C12: 42720
A13: 11 | B13: Shahid Sb For Purchase | C13: 42000
A14: 12 | B14: Sadi Bhai For Purcahse 26-Dec-2025 | C14: 35000
... A64: 62 | B64: Bartan Jali | C64: 60
A65: 63 | B65: Sadi Bhai For Purchase 14-Jan-2026 | C65: =60000-1750-1250 -> 57000
A66: 64 | B66: Ali Passand salary of dec 2025 | C66: 26067
A67: 65 | B67: Ayaz Dishwasheer Advance 14-Jan-2026 | C67: 5000
A68: 66 | B68: Ramzan Waiter advance 17-Jan-2026 | C68: 10000
A69: 67 | B69: Sadi Bhai for purchase 17-Jan-2026 | C69: 25000
A70: 68 | B70: Poran Salry finel setlemnet 17-Jan-2026 | C70: 18133
A71: 68 | B71: Asif Samosa Maker 17-Jan-2026 | C71: 9000
A72: 69 | B72: Spunge 3 nos 17-Jan-2026 | C72: 180
A73: 70 | B73: For Tomato Purchase 18-Jan-2026 | C73: 720
A74: 71 | B74: Dahi,Tomato, Shoping Bag, Rice 19-Jan-2026 | C74: 1970
A75: 72 | B75: Sadi Bhai for Purchase 19-Jan-2026 | C75: =25000-6634 -> 18366
A76: 73 | B76: Sadi Bhai Purchase Sabzi Fruit | C76: 26040
A77: 74 | B77: Cash Handover to Javed sb for deposit | C77: 900000
A78: 75 | B78: Cash Handover to shahid sb for Change | C78: 100000
A79: 76 | B79: Sadi Bhai for Aalo And Tomato Purchase | C79: 15000
A80: 77 | B80: Milk Payment 20-Jan-2026 | C80: 20900
A81: 78 | B81: Shoping Bag 3 Sizes 20-Jan-2026 | C81: 1800
B82: Manzoor Cook Advance 20-Jan-2026 | C82: 10000
A83: Total Advance amount from cash | C83: =SUM(C3:C82) -> 4371561

Sheet Daily material use, price sheet
I1: Working on 18-Jan-26
A2: Date | B2: Day | C2: Meal Type | D2: Material | E2: Qty | F2: Unit | G2: Price | H2: Amount | I2: Total Material Cost
A3: 16-21 Dec-25 | B3: Tue - Sun | C3: Refreshment | D3: Milk Powder | E3: 54.5 | F3: Kg | G3: 1400 | H3: =Table3[[#This Row],[Qty]]*Table3[[#This Row],[Price]] -> 76300
A4: 16-21 Dec-25 | B4: Tue - Sun | C4: Refreshment | D4: Sugar | E4: 159.5 | F4: Kg | G4: 170 | H4: =Table3[[#This Row],[Qty]]*Table3[[#This Row],[Price]] -> 27115
A5: 16-21 Dec-25 | B5: Tue - Sun | C5: All Meals | D5: Red Chilli Powder | E5: 7 | F5: Kg | G5: 650 | H5: =Table3[[#This Row],[Qty]]*Table3[[#This Row],[Price]] -> 4550
A6: 16-21 Dec-25 | B6: Tue - Sun | C6: All Meals | D6: Red Chilli Whole | E6: 1 | F6: Kg | G6: 650 | H6: =Table3[[#This Row],[Qty]]*Table3[[#This Row],[Price]] -> 650
A7: 16-21 Dec-25 | B7: Tue - Sun | C7: All Meals | D7: Rice | E7: 211 | F7: Kg | G7: 300 | H7: =Table3[[#This Row],[Qty]]*Table3[[#This Row],[Price]] -> 63300
A8: 16-21 Dec-25 | B8: Tue - Sun | C8: All Meals | D8: Cooking Oil | E8: 140 | F8: Ltr | G8: 443.33 | H8: =Table3[[#This Row],[Qty]]*Table3[[#This Row],[Price]] -> 62066.2
A9: 16-21 Dec-25 | B9: Tue - Sun | C9: All Meals | D9: Atta Fine | E9: 600 | F9: Kg | G9: 119 | H9: =Table3[[#This Row],[Qty]]*Table3[[#This Row],[Price]] -> 71400
A10: 16-21 Dec-25 | B10: Tue - Sun | C10: All Meals | D10: Atta Chakki | E10: 950 | F10: Kg | G10: 113 | H10: =Table3[[#This Row],[Qty]]*Table3[[#This Row],[Price]] -> 107350
A11: 16-21 Dec-25 | B11: Tue - Sun | C11: Lunch | D11: Coriender Powder | E11: 6 | F11: Kg | G11: 580 | H11: =Table3[[#This Row],[Qty]]*Table3[[#This Row],[Price]] -> 3480
A12: 16-21 Dec-25 | B12: Tue - Sun | C12: Lunch | D12: Zeera | E12: 3.5 | F12: Kg | G12: 1150 | H12: =Table3[[#This Row],[Qty]]*Table3[[#This Row],[Price]] -> 4025
A13: 16-21 Dec-25 | B13: Tue - Sun | C13: All Meals | D13: Brown Piyaz Fried | E13: 23 | F13: Kg | G13: 560 | H13: =Table3[[#This Row],[Qty]]*Table3[[#This Row],[Price]] -> 12880
A14: 16-21 Dec-25 | B14: Tue - Sun | C14: Lunch | D14: Daal Channa | E14: 13 | F14: Kg | G14: 210 | H14: =Table3[[#This Row],[Qty]]*Table3[[#This Row],[Price]] -> 2730
... A53: 16-21 Dec-25 | B53: Tue - Sun | C53: Refreshment | D53: Yogurt | E53: 8 | F53: Kg | G53: 320 | H53: =Table3[[#This Row],[Qty]]*Table3[[#This Row],[Price]] -> 2560
A54: 46013 | B54: Monday | C54: Refreshment | D54: Fresh Milk | E54: 10 | F54: Ltr | G54: 220 | H54: =Table3[[#This Row],[Qty]]*Table3[[#This Row],[Price]] -> 2200
A55: 46013 | B55: Monday | C55: Refreshment | D55: Milk Powder | E55: 11 | F55: Kg | G55: 1400 | H55: =Table3[[#This Row],[Qty]]*Table3[[#This Row],[Price]] -> 15400
A56: 46013 | B56: Monday | C56: Refreshment | D56: Sugar | E56: 22.85 | F56: Kg | G56: 170 | H56: =Table3[[#This Row],[Qty]]*Table3[[#This Row],[Price]] -> 3884.5
A57: 46013 | B57: Monday | C57: All Meals | D57: Rice | E57: 24 | F57: Kg | G57: 300 | H57: =Table3[[#This Row],[Qty]]*Table3[[#This Row],[Price]] -> 7200
A58: 46013 | B58: Monday | C58: All Meals | D58: Cooking Oil | E58: 39 | F58: Ltr | G58: 443.33 | H58: =Table3[[#This Row],[Qty]]*Table3[[#This Row],[Price]] -> 17289.87
A59: 46013 | B59: Monday | C59: All Meals | D59: Atta Fine | E59: 100 | F59: Kg | G59: 119 | H59: =Table3[[#This Row],[Qty]]*Table3[[#This Row],[Price]] -> 11900
A60: 46013 | B60: Monday | C60: All Meals | D60: Atta Chakki | E60: 125 | F60: Kg | G60: 113 | H60: =Table3[[#This Row],[Qty]]*Table3[[#This Row],[Price]] -> 14125
A61: 46013 | B61: Monday | C61: All Meals | D61: Brown Piyaz Fried | E61: 2.5 | F61: Kg | G61: 560 | H61: =Table3[[#This Row],[Qty]]*Table3[[#This Row],[Price]] -> 1400
A62: 46013 | B62: Monday | C62: Lunch | D62: Daal Channa | E62: 3 | F62: Kg | G62: 210 | H62: =Table3[[#This Row],[Qty]]*Table3[[#This Row],[Price]] -> 630
A63: 46013 | B63: Monday | C63: All Meals | D63: Achar Gosht Masala | E63: 0.5 | F63: Kg | G63: 580 | H63: =Table3[[#This Row],[Qty]]*Table3[[#This Row],[Price]] -> 290
A64: 46013 | B64: Monday | C64: All Meals | D64: Pulao Masala | E64: 0.5 | F64: Kg | G64: 580 | H64: =Table3[[#This Row],[Qty]]*Table3[[#This Row],[Price]] -> 290
A65: 46013 | B65: Monday | C65: All Meals | D65: Papri | E65: 10 | F65: Kg | G65: 490 | H65: =Table3[[#This Row],[Qty]]*Table3[[#This Row],[Price]] -> 4900
... A315: 46022 | B315: Wednesday | C315: Lunch | D315: Coriender Powder | E315: 1.5 | F315: Kg | G315: 580 | H315: =Table3[[#This Row],[Qty]]*Table3[[#This Row],[Price]] -> 870
A316: 46022 | B316: Wednesday | C316: Lunch | D316: Match Box | E316: 50 | F316: Box | H316: =Table3[[#This Row],[Qty]]*Table3[[#This Row],[Price]] -> 0
A317: 46022 | B317: Wednesday | C317: Lunch | D317: Coriender Dry Whole | E317: 1 | F317: Kg | G317: 530 | H317: =Table3[[#This Row],[Qty]]*Table3[[#This Row],[Price]] -> 530
A318: 46022 | B318: Wednesday | C318: Lunch | D318: Maida | E318: 12 | F318: Kg | G318: 120 | H318: =Table3[[#This Row],[Qty]]*Table3[[#This Row],[Price]] -> 1440
A319: 46022 | B319: Wednesday | C319: Lunch | D319: Cucumber | E319: 0.5 | F319: Kg | G319: 95 | H319: =Table3[[#This Row],[Qty]]*Table3[[#This Row],[Price]] -> 47.5
A320: 46022 | B320: Wednesday | C320: Lunch | D320: Carrot | E320: 1.25 | F320: Kg | G320: 90 | H320: =Table3[[#This Row],[Qty]]*Table3[[#This Row],[Price]] -> 112.5
A321: 46022 | B321: Wednesday | C321: Lunch | D321: Chukandar | E321: 0.3 | F321: Kg | G321: 50 | H321: =Table3[[#This Row],[Qty]]*Table3[[#This Row],[Price]] -> 15
A322: 46022 | B322: Wednesday | C322: Lunch | D322: Karahi Masala | E322: 0.3 | F322: Kg | G322: 580 | H322: =Table3[[#This Row],[Qty]]*Table3[[#This Row],[Price]] -> 174
A323: 46022 | B323: Wednesday | C323: Lunch | D323: Brown Piyaz Fried | E323: 2 | F323: Kg | G323: 560 | H323: =Table3[[#This Row],[Qty]]*Table3[[#This Row],[Price]] -> 1120
A324: 46022 | B324: Wednesday | C324: Breakfast | D324: Channa | E324: 2 | F324: Kg | G324: 183 | H324: =Table3[[#This Row],[Qty]]*Table3[[#This Row],[Price]] -> 366
A325: 46022 | B325: Wednesday | C325: Lunch | D325: Shopping Bags 12 x16 | E325: 3.5 | F325: Kg | G325: 500 | H325: =Table3[[#This Row],[Qty]]*Table3[[#This Row],[Price]] -> 1750
A326: 46022 | B326: Wednesday | C326: Lunch | D326: Ginger / Adrak | E326: 0.005 | F326: Kg | G326: 350 | H326: =Table3[[#This Row],[Qty]]*Table3[[#This Row],[Price]] -> 1.75
A327: 46022 | B327: Wednesday | C327: Lunch | D327: Salt | E327: 3 | F327: Kg | G327: 12 | H327: =Table3[[#This Row],[Qty]]*Table3[[#This Row],[Price]] -> 36
...

Sheet Voucher
A2: Mujtaba And Borthers
A3: SR# | B3: Date | C3: Name | D3: Amount
A4: 1 | B4: 46023 | C4: Riaz Ali Advance Payment | D4: 11000
A6: Total Pay Amount | D6: 11000
A8: Prepared By | C8: Approved By | D8: Received By
A10: Mujtaba And Borthers
A11: SR# | B11: Date | C11: Name | D11: Amount
A12: 1 | B12: 46023 | C12: Rent For Dags And Fridge | D12: 8000
C13: Tool Tex | D13: 400
A14: Total Pay Amount | D14: =SUM(D12:D13) -> 8400
A16: Prepared By | C16: Approved By | D16: Received By
A18: Mujtaba And Borthers
A19: SR# | B19: Date | C19: Name | D19: Amount
A20: 1 | B20: 46024 | C20: Muhammad Ali Advance Payment | D20: 1000
A22: Total Pay Amount | D22: =SUM(D20:D21) -> 1000
A23: Prepared By | C23: Approved By | D23: Received By
A25: Mujtaba And Borthers
A26: SR# | B26: Date | C26: Name | D26: Amount
A27: 1 | B27: 46024 | C27: Dost Ali Advance Payment | D27: 10000
A29: Total Pay Amount | D29: =SUM(D27:D28) -> 10000
A30: Prepared By | C30: Approved By | D30: Received By
A32: Mujtaba And Borthers
A33: SR# | B33: Date | C33: Name | D33: Amount
A34: 1 | B34: 46024 | C34: Suhrab Advance Payment | D34: 1000
A36: Total Pay Amount | D36: =SUM(D34:D35) -> 1000
A37: Prepared By | C37: Approved By | D37: Received By
A39: Mujtaba And Borthers
A40: SR# | B40: Date | C40: Name | D40: Amount
A41: 1 | B41: 46025 | C41: Hussain Advance Payment | D41: 20000
A43: Total Pay Amount | D43: =SUM(D41:D42) -> 20000
A44: Prepared By | C44: Approved By | D44: Received By
A46: Mujtaba And Borthers
A47: SR# | B47: Date | C47: Name | D47: Amount
A48: 1 | B48: 46025 | C48: Amir Ali Cook Salary for 10 Days(25-Dec to 03Jan 2026) | D48: 16666
A50: Total Pay Amount | D50: =SUM(D48:D49) -> 16666
A51: Prepared By | C51: Approved By | D51: Received By
A53: Mujtaba And Borthers
A54: SR# | B54: Date | C54: Name | D54: Amount
A55: 1 | B55: 46025 | C55: Ashiq hussain Salary for 27 Days(09-Dec to 04Jan 2026) | D55: =1400*27 -> 37800
A57: Total Pay Amount | D57: =SUM(D55:D56) -> 37800
...

Sheet Menu For Executive
A1: Senior Mess Menu
A2: Lunch
A3: SR# | B3: Day | C3: Item Name | D3: Price | E3: GRM
A4: 1 | B4: Monday | C4: Chicken Hara Masala | D4: 225 | E4: 200
A5: 2 | B5: Tuesday | C5: Allo Mattar Pulao | D5: 180 | E5: 600
A6: 3 | B6: Wednesday | C6: Dall Chana Fry/ Dall Mash | D6: 180 | E6: 200
A7: 4 | B7: Thursday | C7: Seasonal Vegetable | D7: 180 | E7: 200
A8: 5 | B8: Friday | C8: Chicken Biryani (2 Pieces) | D8: 320 | E8: 600
A9: 6 | B9: Saturday | C9: Chicken Aalo Curry | D9: 220 | E9: 200
A10: 7 | B10: Sunday
A12: Senior Mess Menu
A13: Dinner
A14: SR# | B14: Day | C14: Item Name | D14: Price | E14: GRM
A15: 1 | B15: Monday | C15: Red Been (Lobia) | D15: 180 | E15: 200
A16: 2 | B16: Tuesday | C16: Beef Aloo Qeema | D16: 270 | E16: 200
A17: 3 | B17: Wednesday | C17: Dall Chawal (450/150) | D17: 200 | E17: 600
A18: 4 | B18: Thursday | C18: Achari Chicken | D18: 225 | E18: 200
A19: 5 | B19: Friday | C19: Seasonal Vegetable | D19: 180 | E19: 200
A20: 6 | B20: Saturday | C20: Vegetable Rice with Chicken Manchorian (450/150) | D20: 350 | E20: 600
A21: 7 | B21: Sunday

Sheet Labor Menu 
A1: Junior Menu
A2: Breakfast
A3: SR# | B3: Day | C3: Item Name | D3: Price | E3: GRM
A4: 1 | B4: Monday | C4: Paratha, Channa, Chay | D4: 30,50,30 | E4: 100
A5: 2 | B5: Tuesday | C5: Paratha, Aloo Bhujia, Chay | D5: 30,50,30 | E5: 100
A6: 3 | B6: Wednesday | C6: Paratha, Anda Aloo/ Anda Omlete, Chay | D6: 30,50,30 | E6: 100
A7: 4 | B7: Thursday | C7: Paratha, Channa, Chay | D7: 30,50,30 | E7: 100
A8: 5 | B8: Friday | C8: Paratha, Aloo Bhujia, Chay | D8: 30,50,30 | E8: 100
A9: 6 | B9: Saturday | C9: Paratha, Anda Aloo, Chay | D9: 30,50,30 | E9: 100
A10: 7 | B10: Sunday | C10: Paratha, Channa, Chay | D10: 30,50,30 | E10: 100
A12: Lunch
A13: SR# | B13: Day | C13: Item Name | D13: Price | E13: GRM
A14: 1 | B14: Monday | C14: Chicken Aloo | D14: 110 | E14: 250
A15: 2 | B15: Tuesday | C15: Dall Mong | D15: 80 | E15: 250
A16: 3 | B16: Wednesday | C16: Chicken Pulao | D16: 180 | E16: 450
A17: 4 | B17: Thursday | C17: Sabzi | D17: 80 | E17: 250
A18: 5 | B18: Friday | C18: Chicken Biryani (1 Piece) | D18: 180 | E18: 450
A19: 6 | B19: Saturday | C19: Sabzi | D19: 80 | E19: 250
A20: 7 | B20: Sunday | C20: Dall Channa palak | D20: 80 | E20: 250
A22: Dinner
A23: SR# | B23: Day | C23: Item Name | D23: Price | E23: GRM
A24: 1 | B24: Monday | C24: Dall Channa | D24: 80 | E24: 250
A25: 2 | B25: Tuesday | C25: Sabzi | D25: 80 | E25: 250
A26: 3 | B26: Wednesday | C26: Curry Pakora/ White Zeera Rice | D26: 80100 | E26: 150/300
A27: 4 | B27: Thursday | C27: Murg Salan | D27: 110 | E27: 250
A28: 5 | B28: Friday | C28: Sabzi | D28: 80 | E28: 250
A29: 6 | B29: Saturday | C29: Dall Masoor | D29: 80 | E29: 250
A30: 7 | B30: Sunday | C30: Dall Chawal | D30: 120 | E30: 150/300

Sheet Steaching Dep
A1: SR# | B1: Date | C1: Item Name | D1: QTY | E1: Price | F1: Department
A2: 1 | B2: 16/12/2025 | C2: Karahi | D2: 1.5Kg | E2: 2100 | F2: Steaching
A3: 2 | B3: 16/12/2025 | C3: Biryani | D3: 1.5Kg | E3: 2400 | F3: Steaching
A4: 3 | B4: 16/12/2025 | C4: Salad | D4: 2 Plate | E4: 100 | F4: Steaching
A5: 4 | B5: 16/12/2025 | C5: Roti | D5: 6 | E5: 90 | F5: Steaching
A6: 5 | B6: 16/12/2025 | C6: Boild Egg | D6: 4 | E6: 200 | F6: Steaching
A7: 6 | B7: 16/12/2025 | C7: Fry Egg | D7: 3 | E7: 150 | F7: Steaching
A8: 7 | B8: 16/12/2025 | C8: Paratha | D8: 8 | E8: 280 | F8: Steaching
A9: 8 | B9: 16/12/2025 | C9: Tea | D9: 4 | E9: 140 | F9: Steaching
A10: 9 | B10: 16/12/2025 | C10: Lemaon | D10: 2 | E10: 20 | F10: Steaching
A11: Grand Total Amount | E11: =SUM(E2:E10) -> 5480
A12: Preapred By | F12: Clint Signature
A13: SR# | B13: Date | C13: Item Name | D13: QTY | E13: Price | F13: Department
A14: Breakfast
A15: 1 | B15: 17/12/2025 | C15: Night Tea | D15: 5 | E15: 150 | F15: Steaching
A16: 2 | B16: 17/12/2025 | C16: Parathy | D16: 10 | E16: 350 | F16: Steaching
A17: 3 | B17: 17/12/2025 | C17: Anday | D17: 5 | E17: 250 | F17: Steaching
A18: Lunch
A19: 1 | B19: 17/12/2025 | C19: Anday | D19: 4 | E19: 200 | F19: Steaching
A20: 2 | B20: 17/12/2025 | C20: Salad | D20: 2 | E20: 40 | F20: Steaching
A21: 3 | B21: 17/12/2025 | C21: Chicken Qorma | D21: 3 | E21: 600 | F21: Steaching
A22: 4 | B22: 17/12/2025 | C22: Roti | D22: 8 | E22: 120 | F22: Steaching
A23: 5 | B23: 17/12/2025 | C23: Chicken Qorma | D23: 3 | E23: 600 | F23: Steaching
A24: 6 | B24: 17/12/2025 | C24: Roti | D24: 8 | E24: 120 | F24: Steaching
A25: 7 | B25: 17/12/2025 | C25: Salad | D25: 2 | E25: 40 | F25: Steaching
A26: 8 | B26: 17/12/2025 | C26: Raita | D26: 1 | E26: 120 | F26: Steaching
A27: 9 | B27: 17/12/2025 | C27: Tea | D27: 10 | E27: 350 | F27: Steaching
A28: Dinner
A29: 1 | B29: 17/12/2025 | C29: Biryani | D29: 2 Kg | E29: 3200 | F29: Steaching
A30: 2 | B30: 17/12/2025 | C30: Karahi | D30: 1kg | E30: 1600 | F30: Steaching
A31: 3 | B31: 17/12/2025 | C31: Salad | D31: 2 | E31: 40 | F31: Steaching
A32: 4 | B32: 17/12/2025 | C32: Raita | D32: 1 | E32: 120 | F32: Steaching
A33: 5 | B33: 17/12/2025 | C33: Roti | D33: 15 | E33: 225 | F33: Steaching
A34: Grand Total Amount | E34: =E15+E16+E17+E19+E20+E21+E22+E23+E24+E25+E26+E27+E29+E30+E31+E32+E33 -> 8125
A35: Preapred By | F35: Clint Signature
A36: SR# | B36: Date | C36: Item Name | D36: QTY | E36: Price | F36: Department
A37: 1 | B37: 18/12/2025 | C37: Partahy | D37: 7 | E37: 245 | F37: Steaching
A38: 2 | B38: 18/12/2025 | C38: Half Fry Egg | D38: 5 | E38: 250 | F38: Steaching
A39: 3 | B39: 18/12/2025 | C39: White Rice | D39: 1Kg | E39: 1000 | F39: Steaching
A40: 4 | B40: 18/12/2025 | C40: Biryani | D40: 1Kg | E40: 1600 | F40: Steaching
...

Sheet Steaching Deprt Summary 
A1: Mujtaba and Brothers (Bill)
A2: SR# | B2: Date | C2: Name | D2: Depart | E2: Amount | F2: Signature | G2: Received Amount Date
A3: 1 | B3: 16 Dec to 09 Jan 2026 | C3: Talha | D3: Steaching | E3: 181270
A4: 2 | B4: 16 Dec to 09 Jan 2026
A5: 3 | B5: 16 Dec to 09 Jan 2026
A6: 4 | B6: 16 Dec to 09 Jan 2026
A7: Total Amount
A8: Preapred BY | G8: Clint Signature
A10: SUMMARY OF STEACHING OVERTIME DEPART
A11: SR# | B11: Date | C11: Name | D11: Amount | E11: Depart
A12: 1 | B12: 46032 | C12: Atar Sb | D12: ='Steaching Dep'!E455 -> 8680 | E12: Steaching
A13: 2 | B13: 46033 | C13: Atar Sb | D13: ='Steaching Dep'!E467 -> 3915 | E13: Steaching
A14: 3 | B14: 46034 | C14: Atar Sb | D14: ='Steaching Dep'!E486 -> 5520 | E14: Steaching
A15: 4 | B15: 46035 | C15: Atar Sb | D15: ='Steaching Dep'!E504 -> 7205 | E15: Steaching
A16: 5 | B16: 46036 | C16: Atar Sb | D16: ='Steaching Dep'!E526 -> 6095 | E16: Steaching
A17: 6 | B17: 46037 | C17: Atar Sb | D17: ='Steaching Dep'!E551 -> 13345 | E17: Steaching
A18: TOTAL AMOUNT | D18: =SUM(D12:D17) -> 44760
A19: Preapred By | E19: Clint Signature
A22: Admin Sig

Sheet Steaching Thakydar overtime
A1: SR# | B1: Date | C1: Item Name | D1: QTY | E1: Price | F1: Department
A2: 1 | B2: 17/12/2025 | C2: Sabzi | D2: 23 | E2: 1840 | F2: Steaching
A3: 2 | B3: 17/12/2025 | C3: Roti | D3: 69 | E3: 1035 | F3: Steaching
A4: 3 | B4: 17/12/2025 | C4: Tea | D4: 23 | E4: 805 | F4: Steaching
A5: Grand Total Amount | E5: =SUM(E2:E4) -> 3680
A6: Preapred By | F6: Clint Signature
A7: SR# | B7: Date | C7: Item Name | D7: QTY | E7: Price | F7: Department
A8: 1 | B8: 18/12/2025 | C8: Chay | D8: 18 | E8: =D8*35 -> 630 | F8: Steaching
A9: 2 | B9: 18/12/2025 | C9: Dall | D9: 18 | E9: =D9*80 -> 1440 | F9: Steaching
A10: 3 | B10: 18/12/2025 | C10: Roti | D10: 54 | E10: =D10*15 -> 810 | F10: Steaching
A11: Grand Total Amount | E11: =SUM(E8:E10) -> 2880
A12: Preapred By | F12: Clint Signature
A13: SR# | B13: Date | C13: Item Name | D13: QTY | E13: Price | F13: Department
A14: 1 | B14: 25/12/2025 | C14: Chai | D14: 1 | E14: 35 | F14: Steaching
A15: 2 | B15: 25/12/2025 | C15: Roti | D15: 38 | E15: 570 | F15: Steaching
A16: 3 | B16: 25/12/2025 | C16: Ch- Aalo Ghost | D16: 18 | E16: 1980 | F16: Steaching
A17: Grand Total Amount | E17: =SUM(E14:E16) -> 2585
A18: Preapred By | F18: Clint Signature
A19: SR# | B19: Date | C19: Item Name | D19: QTY | E19: Price | F19: Department
A20: 1 | B20: 26/12/2025 | C20: Aalo Biryani | D20: 15 | E20: =D20*120 -> 1800 | F20: Steaching
A21: Grand Total Amount | E21: =SUM(E20:E20) -> 1800
A22: Preapred By | F22: Clint Signature
A23: SR# | B23: Date | C23: Item Name | D23: QTY | E23: Price | F23: Department
A24: 1 | B24: 27/12/2025 | C24: Sabzi | D24: 17 | E24: =D24*80 -> 1360 | F24: Steaching
A25: 2 | B25: 27/12/2025 | C25: Roti | D25: 51 | E25: =D25*15 -> 765 | F25: Steaching
A26: 3 | B26: 27/12/2025 | C26: Chai | D26: 11 | E26: =D26*35 -> 385 | F26: Steaching
A27: Grand Total Amount | E27: =SUM(E24:E24) -> 1360
A28: Preapred By | F28: Clint Signature
A29: SR# | B29: Date | C29: Item Name | D29: QTY | E29: Price | F29: Department
A30: 1 | B30: 29/12/2025 | C30: Channa Dal | D30: 17 | E30: =D30*80 -> 1360 | F30: Steaching
A31: 2 | B31: 29/12/2025 | C31: Roti | D31: 51 | E31: =D31*15 -> 765 | F31: Steaching
A32: Grand Total Amount | E32: =SUM(E30:E31) -> 2125
A33: Preapred By | F33: Clint Signature
A34: SR# | B34: Date | C34: Item Name | D34: QTY | E34: Price | F34: Department
A35: 1 | B35: 30/12/2025 | C35: Sabzi | D35: 10 | E35: =D35*80 -> 800 | F35: Steaching
A36: 2 | B36: 30/12/2025 | C36: Roti | D36: 30 | E36: =D36*15 -> 450 | F36: Steaching
A37: Grand Total Amount | E37: =SUM(E35:E36) -> 1250
A38: Preapred By | F38: Clint Signature
A39: SR# | B39: Date | C39: Item Name | D39: QTY | E39: Price | F39: Department
A40: 1 | B40: 46022 | C40: Sabzi | D40: 8 | E40: =D40*80 -> 640 | F40: Steaching
...

Sheet Summary Amanat Sb 
A1: SUMMARY OF STEACHING OVERTIME DEPART
A2: SR# | B2: Date | C2: Name | D2: Amount | E2: Depart
A3: 1 | B3: 46023 | C3: Amant Sb | D3: 7840 | E3: Steaching
A4: 2 | B4: 46024 | C4: Amant Sb | D4: 2750 | E4: Steaching
A5: 3 | B5: 46028 | C5: Amant Sb | D5: 775 | E5: Steaching
A6: 4 | B6: 46030 | C6: Amant Sb | D6: 2310 | E6: Steaching
A7: 5 | B7: 46030 | C7: Amant Sb | D7: 1800 | E7: Steaching
A8: 6 | B8: 46031 | C8: Amant Sb | D8: 2880 | E8: Steaching
A9: 7 | B9: 46031 | C9: Amant Sb | D9: 2625 | E9: Steaching
A10: 8 | B10: 46032 | C10: Amant Sb | D10: 1750 | E10: Steaching
A11: 9 | B11: 46036 | C11: Amant Sb | D11: 2640 | E11: Steaching
A12: 10 | B12: 46037 | C12: Amant Sb | D12: 3875 | E12: Steaching
A13: 11 | B13: 46037 | C13: Amant Sb | D13: 2405 | E13: Steaching
A14: TOTAL AMOUNT | D14: =SUM(D3:D13) -> 31650
A15: Preapred By | E15: Clint Signature
A18: Admin Sig

Sheet Dying
A1: SR# | B1: Date | C1: Item Name | D1: QTY | E1: Price | F1: Department
A2: 1 | B2: 16/12/2025 | C2: Chicken Karahi | D2: 1 Plate | E2: 200 | F2: Dying
A3: 2 | B3: 16/12/2025 | C3: Dall | D3: 1 Plate | E3: 80 | F3: Dying
A4: 3 | B4: 16/12/2025 | C4: Roti | D4: 5 | E4: 90 | F4: Dying
A5: 4 | B5: 16/12/2025 | C5: Salad | F5: Dying
A6: Grand Total Amount | E6: =SUM(E2:E5) -> 370
A8: Preapred By | F8: Clint Signature
A11: SR# | B11: Date | C11: Item Name | D11: QTY | E11: Price | F11: Department
A12: 1 | B12: 17/12/2025 | C12: Chicken Karahi | D12: 2 Plate | E12: 400 | F12: Dying
A13: 2 | B13: 17/12/2025 | C13: Cold Drink | D13: 1 | E13: 70 | F13: Dying
A14: 3 | B14: 17/12/2025 | C14: Roti | D14: 6 | E14: 90 | F14: Dying
A15: 4 | B15: 17/12/2025 | C15: Salad | D15: 1 | E15: 20 | F15: Dying
A16: Grand Total Amount | E16: =SUM(E12:E15) -> 580
A18: Preapred By | F18: Clint Signature
A21: SR# | B21: Date | C21: Item Name | D21: QTY | E21: Price | F21: Department
A22: 1 | B22: 18/12/2025 | C22: Chicken Stew | D22: 1 Plate | E22: 200 | F22: Dying
A23: 2 | B23: 18/12/2025 | C23: Roti | D23: 3 | E23: 45 | F23: Dying
A24: 3 | B24: 18/12/2025 | C24: Salad | D24: 1 | E24: 20 | F24: Dying
A26: Grand Total Amount | E26: =SUM(E22:E25) -> 265
A28: Preapred By | F28: Clint Signature
A30: SR# | B30: Date | C30: Item Name | D30: QTY | E30: Price | F30: Department
A31: 1 | B31: 19/12/2025 | C31: Biryani | D31: 5 | E31: 900 | F31: Dying
A32: 2 | B32: 19/12/2025 | C32: Salad | D32: 2 | E32: 50 | F32: Dying
A33: 3 | B33: 19/12/2025 | C33: Raita | D33: 1 | E33: 50 | F33: Dying
A34: 4 | B34: 19/12/2025 | C34: ColdDrink | D34: 2 | E34: 140 | F34: Dying
A35: 5 | B35: 19/12/2025 | C35: Fruit Chat | D35: 2 | E35: 240 | F35: Dying
A36: Grand Total Amount | E36: =SUM(E31:E35) -> 1380
A38: Preapred By | F38: Clint Signature
A41: SR# | B41: Date | C41: Item Name | D41: QTY | E41: Price | F41: Department
A42: 1 | B42: 20/12/2025 | C42: Fruit Chat | D42: 1 | E42: 120 | F42: Dying
A43: 2 | B43: 20/12/2025 | C43: Biscut | D43: 3 | E43: 120 | F43: Dying
A44: 3
A45: 4
A46: 5
A47: Grand Total Amount | E47: =SUM(E42:E46) -> 240
A49: Preapred By | F49: Clint Signature
A52: SR# | B52: Date | C52: Item Name | D52: QTY | E52: Price | F52: Department
A53: 1 | B53: 22/12/2025 | C53: Ch Karahi | D53: 1 | E53: 200 | F53: Dying
A54: 2 | B54: 22/12/2025 | C54: Anda channa | D54: 1 | E54: 110 | F54: Dying
A55: 3 | B55: 22/12/2025 | C55: Roti | D55: 5 | E55: =D55*15 -> 75 | F55: Dying
...

Sheet Summary Of Dying Depart 
A1: SUMMARY OF DYING DEPART
A2: SR# | B2: Date | C2: Name | D2: Amount | E2: Depart
A3: 1 | B3: 46007 | C3: Waqas SB | D3: 370 | E3: Dying
A4: 2 | B4: 46008 | C4: Waqas SB | D4: 580 | E4: Dying
A5: 3 | B5: 46009 | C5: Waqas SB | D5: 265 | E5: Dying
A6: 4 | B6: 46010 | C6: Waqas SB | D6: 1380 | E6: Dying
A7: 5 | B7: 46011 | C7: Waqas SB | D7: 240 | E7: Dying
A8: 6 | B8: 46012 | C8: Waqas SB | D8: 720 | E8: Dying
A9: 7 | B9: 46014 | C9: Waqas SB | D9: 340 | E9: Dying
A10: 8 | B10: 46015 | C10: Waqas SB | D10: 1050 | E10: Dying
A11: 9 | B11: 46017 | C11: Waqas SB | D11: 1700 | E11: Dying
A12: 10 | B12: 46018 | C12: Waqas SB | D12: 1320 | E12: Dying
A13: 11 | B13: 46020 | C13: Waqas SB | D13: 720 | E13: Dying
A14: 12 | B14: 46021 | C14: Waqas SB | D14: 1770 | E14: Dying
A15: 13 | B15: 46022 | C15: Waqas SB | D15: 1575 | E15: Dying
A16: Grand Total Amount | D16: =SUM(D3:D15) -> 12030
A18: SUMMARY OF DYING DEPART
A19: SR# | B19: Date | C19: Name | D19: Amount | E19: Depart
A20: 1 | B20: 46023 | C20: Waqas SB | D20: 1585 | E20: Dying
A21: 2 | B21: 46024 | C21: Waqas SB | D21: 1160 | E21: Dying
A22: 3 | B22: 46025 | C22: Waqas SB | D22: 1065 | E22: Dying
A23: 4 | B23: 46027 | C23: Waqas SB | D23: 740 | E23: Dying
A24: 5 | B24: 46027 | C24: Waqas SB | D24: 280 | E24: Dying
A25: 6 | B25: 46028 | C25: Waqas SB | D25: 650 | E25: Dying
A26: 7 | B26: 46029 | C26: Waqas SB | D26: 625 | E26: Dying
A27: 8 | B27: 46029 | C27: Waqas SB | D27: 640 | E27: Dying
A28: 9 | B28: 46030 | C28: Waqas SB | D28: 920 | E28: Dying
A29: 10 | B29: 46031 | C29: Waqas SB | D29: 870 | E29: Dying
A30: 11 | B30: 46032 | C30: Waqas SB | D30: 445 | E30: Dying
A31: 12 | B31: 46034 | C31: Waqas SB | D31: 695 | E31: Dying
... A39: 20 | B39: 46037 | C39: Waqas SB | D39: 280 | E39: Dying
A40: Grand Total Amount | D40: =SUM(D20:D39) -> 15510
A41: Preapred By | E41: Clint Signature
A45: Admin Sig

Sheet Admin
A1: SR# | B1: Date | C1: Item Name | D1: QTY | E1: Price | F1: Department
A2: 1 | B2: 16/12/2025 | C2: Chicken Karahi | D2: 4 Plate | E2: 800 | F2: Admin
A3: 2 | B3: 16/12/2025 | C3: Dall | D3: 1 Plate | E3: 80 | F3: Admin
A4: 3 | B4: 16/12/2025 | C4: Roti | D4: 15 | E4: 225 | F4: Admin
A5: 4 | B5: 16/12/2025 | C5: Salad | D5: 1 | E5: 20 | F5: Admin
A6: Grand Total Amount | E6: =SUM(E2:E5) -> 1125
A8: Preapred By | F8: Clint Signature
A11: SR# | B11: Date | C11: Item Name | D11: QTY | E11: Price | F11: Department
A12: 1 | B12: 17/12/2025 | C12: Boil Egg | D12: 1 | E12: 50 | F12: Admin
A13: 2 | B13: 17/12/2025 | C13: Cake Rus | D13: 1 | E13: 120 | F13: Admin
A14: 3 | B14: 17/12/2025 | C14: Cake | D14: 1 | E14: 80 | F14: Admin
A15: 4 | B15: 17/12/2025 | C15: Chicken Karahi | D15: 1 Plate | E15: 200 | F15: Admin
A16: 5 | B16: 17/12/2025 | C16: Roti | D16: 4 | E16: 60 | F16: Admin
A17: 6 | B17: 17/12/2025 | C17: Salad | D17: 1 | E17: 20 | F17: Admin
A18: Grand Total Amount | E18: =SUM(E12:E17) -> 530
A20: Preapred By | F20: Clint Signature
A23: SR# | B23: Date | C23: Item Name | D23: QTY | E23: Price | F23: Department
A24: 1 | B24: 17/12/2025 | C24: Chicken Qorma | D24: 4 | E24: 800 | F24: Admin
A25: 2 | B25: 17/12/2025 | C25: Roti | D25: 10 | E25: 150 | F25: Admin
A26: 3 | B26: 17/12/2025 | C26: Salad | D26: 2 | E26: 40 | F26: Admin
A27: Grand Total Amount | E27: =SUM(E24:E26) -> 990
A29: Preapred By | F29: Clint Signature
A31: SR# | B31: Date | C31: Item Name | D31: QTY | E31: Price | F31: Department
A32: 1 | B32: 18/12/2025 | C32: Chicken Stew | D32: 2 | E32: 400 | F32: Admin
A33: 2 | B33: 18/12/2025 | C33: Salad | D33: 1 | E33: 20 | F33: Admin
A34: 3 | B34: 18/12/2025 | C34: Tea | D34: 1 | E34: 35 | F34: Admin
A35: 4 | B35: 18/12/2025 | C35: Roti | D35: 10 | E35: 150 | F35: Admin
A36: Grand Total Amount | E36: =SUM(E32:E35) -> 605
A38: Preapred By | F38: Clint Signature
A40: SR# | B40: Date | C40: Item Name | D40: QTY | E40: Price | F40: Department
A41: 1 | B41: 18/12/2025 | C41: Dall | D41: 2 | E41: 160 | F41: Admin
A42: 2 | B42: 18/12/2025 | C42: Roti | D42: 6 | E42: 90 | F42: Admin
A43: 3 | B43: 18/12/2025 | C43: Tea | D43: 2 | E43: 70 | F43: Admin
A44: 4 | B44: 18/12/2025 | C44: Biryani | D44: 1 Pltae | E44: 170 | F44: Admin
A45: 5 | B45: 18/12/2025 | C45: Roti | D45: 5 | E45: 75
A47: Grand Total Amount | E47: =SUM(E41:E46) -> 565
A49: Preapred By | F49: Clint Signature
A51: SR# | B51: Date | C51: Item Name | D51: QTY | E51: Price | F51: Department
A52: 1 | B52: 19/12/2025 | C52: Biryani | D52: 1 | E52: 180 | F52: Admin
A53: 2 | B53: 19/12/2025 | C53: Roti | D53: 3 | E53: 45 | F53: Admin
...

Sheet Summary of Admin 
A1: SUMMARY OF ADMIN DEPART
A2: SR# | B2: Date | C2: Name | D2: Amount | E2: Depart
A3: 1 | B3: 46009 | C3: Malik Riaz Sb | D3: 605 | E3: Admin
A4: 2 | B4: 46010 | C4: Malik Riaz Sb | D4: 200 | E4: Admin
A5: 3 | B5: 46013 | C5: Malik Riaz Sb | D5: 190 | E5: Admin
A6: 4 | B6: 46014 | C6: Malik Riaz Sb | D6: 530 | E6: Admin
A7: 5 | B7: 46014 | C7: Malik Riaz Sb | D7: 3220 | E7: Admin
A8: 6 | B8: 46015 | C8: Malik Riaz Sb | D8: 175 | E8: Admin
A9: 7 | B9: 46020 | C9: Malik Riaz Sb | D9: 1440 | E9: Admin
A10: 8 | B10: 46021 | C10: Malik Riaz Sb | D10: 1755 | E10: Admin
A11: 9 | B11: 46022 | C11: Malik Riaz Sb | D11: 1340 | E11: Admin
A12: Grand Total Amount | D12: =SUM(D3:D11) -> 9455
A14: SUMMARY OF ADMIN DEPART
A15: SR# | B15: Date | C15: Name | D15: Amount | E15: Depart
A16: 1 | B16: 46023 | C16: Malik Riaz Sb | D16: 200 | E16: Admin
A17: 2 | B17: 46024 | C17: Malik Riaz Sb | D17: 840 | E17: Admin
A18: 3 | B18: 46024 | C18: Malik Riaz Sb | D18: 760 | E18: Admin
A19: 4 | B19: 46027 | C19: Malik Riaz Sb | D19: 620 | E19: Admin
A20: 5 | B20: 46027 | C20: Malik Riaz Sb | D20: 560 | E20: Admin
A21: 6 | B21: 46027 | C21: Malik Riaz Sb | D21: 590 | E21: Admin
A22: 7 | B22: 46028 | C22: Malik Riaz Sb | D22: 620 | E22: Admin
A23: 8 | B23: 46028 | C23: Malik Riaz Sb | D23: 1700 | E23: Admin
A24: 9 | B24: 46028 | C24: Malik Riaz Sb | D24: 280 | E24: Admin
A25: 10 | B25: 46028 | C25: Malik Riaz Sb | D25: 340 | E25: Admin
A26: 11 | B26: 46028 | C26: Malik Riaz Sb | D26: 1110 | E26: Admin
A27: 12 | B27: 46029 | C27: Malik Riaz Sb | D27: 240 | E27: Admin
A28: 13 | B28: 46030 | C28: Malik Riaz Sb | D28: 1210 | E28: Admin
A29: Grand Total Amount | D29: =SUM(D16:D28) -> 9070

Sheet Printing
A1: SR# | B1: Date | C1: Item Name | D1: QTY | E1: Price | F1: Department
A2: 1 | B2: 16/12/2025 | C2: Chicken Karahi | D2: 2 Plate | E2: 400 | F2: Printing
A3: 2 | B3: 16/12/2025 | C3: Chawal | D3: 2 | E3: 200 | F3: Printing
A4: 3 | B4: 16/12/2025 | C4: Dall | D4: 2 | E4: 160 | F4: Printing
A5: 4 | B5: 16/12/2025 | C5: Roti | D5: 5 | E5: 75 | F5: Printing
A6: 5 | B6: 16/12/2025 | C6: Salad | D6: 2 | E6: 50 | F6: Printing
A7: Grand Total Amount | E7: =SUM(E2:E6) -> 885
A9: Preapred By | F9: Clint Signature
A11: SR# | B11: Date | C11: Item Name | D11: QTY | E11: Price | F11: Department
A12: 1 | B12: 46036 | C12: Sp-Ch-Pulao | D12: 4 | E12: =D12*320 -> 1280 | F12: Printing
A13: 2 | B13: 46036 | C13: Salad | D13: 4 | E13: =D13*30 -> 120 | F13: Printing
A14: 3 | B14: 46036 | C14: Dahi | D14: 0.5 | E14: =D14*400 -> 200 | F14: Printing
A15: 4 | B15: 46036 | C15: Cold Drink | D15: 4 | E15: =D15*70 -> 280 | F15: Printing
A16: 5 | B16: 46036 | C16: Roti | D16: 4 | E16: =D16*15 -> 60 | F16: Printing
A17: Grand Total Amount | E17: =SUM(E12:E16) -> 1940
A19: Preapred By | F19: Clint Signature
A22: SUMMARY OF SAMPLE DEPART
A23: SR# | B23: Date | C23: Name | D23: Amount | E23: Depart
A24: 1 | B24: 46036 | C24: Waseem Sb | D24: 1940 | E24: Printing
A25: Grand Total Amount | D25: =SUM(D24:D24) -> 1940
A26: Preapred By | E26: Clint Signature
A31: Admin Sig

Sheet Sample
A1: SR# | B1: Date | C1: Item Name | D1: QTY | E1: Price | F1: Department
A2: 1 | B2: 16/12/2025 | C2: Dall | D2: 4 | E2: 320 | F2: Sampl
A3: 2 | B3: 16/12/2025 | C3: Chawal | D3: 4 | E3: 400 | F3: Sampl
A4: 3 | B4: 16/12/2025 | C4: Chicken Karahi | D4: 4 | E4: 800 | F4: Sampl
A5: 4 | B5: 16/12/2025 | C5: Roti | D5: 6 | E5: 90 | F5: Sampl
A6: 5 | B6: 16/12/2025 | C6: Salad | D6: 1 Bowl | E6: 200 | F6: Sampl
A7: 6 | B7: 16/12/2025 | C7: Cold Drink | D7: 4 | E7: 280 | F7: Sampl
A8: Grand Total Amount | E8: =SUM(E2:E7) -> 2090
A10: Preapred By | F10: Clint Signature
A13: SR# | B13: Date | C13: Item Name | D13: QTY | E13: Price | F13: Department
A14: 1 | B14: 18/12/2025 | C14: Chicken Biryani | D14: 5 | E14: 800 | F14: Sampl
A15: 2 | B15: 18/12/2025 | C15: Salad | D15: 2 | E15: 40 | F15: Sampl
A16: 3 | B16: 18/12/2025 | C16: Cold Drink | D16: 5 | E16: 350 | F16: Sampl
A20: Grand Total Amount | E20: =SUM(E14:E19) -> 1190
A22: Preapred By | F22: Clint Signature
A25: SR# | B25: Date | C25: Item Name | D25: QTY | E25: Price | F25: Department
A26: 1 | B26: 19/12/2025 | C26: Chicken Biryani | D26: 1Kg | E26: 1600 | F26: Sampl
A27: 2 | B27: 19/12/2025 | C27: Salad | D27: 2 | E27: 40 | F27: Sampl
A28: 3 | B28: 19/12/2025 | C28: Cold Drink | D28: 4 | E28: 280 | F28: Sampl
A32: Grand Total Amount | E32: =SUM(E26:E31) -> 1920
A34: Preapred By | F34: Clint Signature
A36: SR# | B36: Date | C36: Item Name | D36: QTY | E36: Price | F36: Department
A37: 1 | B37: 20/12/2025 | C37: Biscut | E37: 40 | F37: Sampl
A38: 2 | B38: 20/12/2025 | C38: Salad | D38: 2 | E38: 40 | F38: Sampl
A39: 3 | B39: 20/12/2025 | C39: Cold Drink | E39: 300 | F39: Sampl
A40: 4 | B40: 20/12/2025 | C40: Fruit Chat | D40: 1 | E40: 120 | F40: Sampl
A41: 5 | B41: 20/12/2025 | C41: Tissue Box | D41: 1 | E41: 270 | F41: Sampl
A42: 6 | B42: 20/12/2025 | C42: Karahi | D42: 4 | E42: 800 | F42: Sampl
A43: 7 | B43: 20/12/2025 | C43: Roti | D43: 10 | E43: 150 | F43: Sampl
A44: Grand Total Amount | E44: =SUM(E37:E43) -> 1720
A46: Preapred By | F46: Clint Signature
A48: SR# | B48: Date | C48: Item Name | D48: QTY | E48: Price | F48: Department
A49: 1 | B49: 20/12/2025 | C49: Aloo Biryani | D49: 72 | E49: =D49*110 -> 7920 | F49: Sampl
A50: Grand Total Amount | E50: =SUM(E49:E49) -> 7920
A52: Preapred By | F52: Clint Signature
A55: SR# | B55: Date | C55: Item Name | D55: QTY | E55: Price | F55: Department
A56: 1 | B56: 22/12/2025 | C56: Ch- Karahi | D56: 3 | E56: 600 | F56: Sampl
A57: 2 | B57: 22/12/2025 | C57: Roti | D57: 8 | E57: 120 | F57: Sampl
A58: 3 | B58: 22/12/2025 | C58: Salad | D58: 1 | E58: 20 | F58: Sampl
A59: 4 | B59: 22/12/2025 | C59: Cold Drink | D59: 3 | E59: 210 | F59: Sampl
...

Sheet Summary of Sample Depart
A1: SUMMARY OF SAMPLE DEPART
A2: SR# | B2: Date | C2: Name | D2: Amount | E2: Depart
A3: 1 | B3: 46007 | C3: Saeed Sb | D3: 2090 | E3: Sample
A4: 2 | B4: 46009 | C4: Saeed Sb | D4: 1190 | E4: Sample
A5: 3 | B5: 46010 | C5: Saeed Sb | D5: 1920 | E5: Sample
A6: 4 | B6: 46011 | C6: Saeed Sb | D6: 1720 | E6: Sample
A7: 5 | B7: 46011 | C7: Saeed Sb | D7: 7920 | E7: Sample
A8: 6 | B8: 46013 | C8: Saeed Sb | D8: 950 | E8: Sample
A9: 7 | B9: 46014 | C9: Saeed Sb | D9: 9790 | E9: Sample
A10: 8 | B10: 46014 | C10: Saeed Sb | D10: 1325 | E10: Sample
A11: 10 | B11: 46015 | C11: Saeed Sb | D11: 1300 | E11: Sample
A12: 11 | B12: 46015 | C12: Saeed Sb | D12: 10560 | E12: Sample
A13: 13 | B13: 46017 | C13: Saeed Sb | D13: 9900 | E13: Sample
A14: 14 | B14: 46017 | C14: Saeed Sb | D14: 1340 | E14: Sample
... A16: 16 | B16: 46022 | C16: Sohail Sb | D16: 895 | E16: Sample
A17: Grand Total Amount | D17: =SUM(D3:D16) -> 59040
A19: SUMMARY OF SAMPLE DEPART
A20: SR# | B20: Date | C20: Name | D20: Amount | E20: Depart
A21: 1 | B21: 46023 | C21: Sohail Sb | D21: 710 | E21: Sample
A22: 2 | B22: 46023 | C22: Sohail Sb | D22: 8800 | E22: Sample
A23: 3 | B23: 46024 | C23: Sohail Sb | D23: 420 | E23: Sample
A24: 4 | B24: 46024 | C24: Sohail Sb | D24: 10340 | E24: Sample
A25: 5 | B25: 46025 | C25: Sohail Sb | D25: 1090 | E25: Sample
A26: 6 | B26: 46027 | C26: Sohail Sb | D26: 5350 | E26: Sample
A27: 7 | B27: 46028 | C27: Sohail Sb | D27: 750 | E27: Sample
A28: 8 | B28: 46029 | C28: Sohail Sb | D28: 560 | E28: Sample
A29: 9 | B29: 46030 | C29: Sohail Sb | D29: 915 | E29: Sample
A30: 10 | B30: 46030 | C30: Sohail Sb | D30: 9240 | E30: Sample
A31: 11 | B31: 46031 | C31: Sohail Sb | D31: 1010 | E31: Sample
A32: 12 | B32: 46031 | C32: Sohail Sb | D32: 7805 | E32: Sample
... A38: 18 | B38: 46037 | C38: Sohail Sb | D38: 3405 | E38: Sample
A39: Grand Total Amount | D39: =SUM(D21:D38) -> 70655
A40: Preapred By | E40: Clint Signature
A44: Admin Sig

Sheet Maintences 
A1: SR# | B1: Date | C1: Item Name | D1: QTY | E1: Price | F1: Department
A2: 1 | B2: 20/12/2025 | C2: Rice | D2: 1 | E2: 110 | F2: Maintences
A3: 2 | B3: 20/12/2025 | C3: Karahi | D3: 2 | E3: 240 | F3: Maintences
A4: 3 | B4: 20/12/2025 | C4: Roti | D4: 6 | E4: 90 | F4: Maintences
A6: Grand Total Amount | E6: =SUM(E2:E5) -> 440
A8: Preapred By | F8: Clint Signature
A10: SR# | B10: Date | C10: Item Name | D10: QTY | E10: Price | F10: Department
A11: 1 | B11: 22/12/2025 | C11: Ch- Karahi | D11: 1 | E11: 200 | F11: Maintences
A12: 2 | B12: 22/12/2025 | C12: Sabzi | D12: 1 | E12: 80 | F12: Maintences
A13: 3 | B13: 22/12/2025 | C13: Roti | D13: 6 | E13: 90 | F13: Maintences
A15: Grand Total Amount | E15: =SUM(E11:E14) -> 370
A17: Preapred By | F17: Clint Signature
A19: SR# | B19: Date | C19: Item Name | D19: QTY | E19: Price | F19: Department
A20: 1 | B20: 22/12/2025 | C20: Ch- Karahi | D20: 1 | E20: 200 | F20: Maintences
A21: 2 | B21: 22/12/2025 | C21: Anda Channa | D21: 1 | E21: 110 | F21: Maintences
A22: 3 | B22: 22/12/2025 | C22: Pulao | D22: 1 | E22: 120 | F22: Maintences
A23: 4 | B23: 22/12/2025 | C23: Dall | D23: 1 | E23: 80 | F23: Maintences
A24: 5 | B24: 22/12/2025 | C24: Roti | D24: 6 | E24: 90 | F24: Maintences
A25: 6 | B25: 22/12/2025 | C25: Chai | D25: 2 | E25: 70 | F25: Maintences
A26: Grand Total Amount | E26: =SUM(E20:E25) -> 670
A28: Preapred By | F28: Clint Signature
A30: SR# | B30: Date | C30: Item Name | D30: QTY | E30: Price | F30: Department
A31: 1 | B31: 23/12/2025 | C31: Chai | D31: 6 | E31: 90 | F31: Maintences
A32: 2 | B32: 23/12/2025 | C32: Parathy | D32: 3 | E32: 105 | F32: Maintences
A33: 3 | B33: 23/12/2025 | C33: Channay | D33: 1 | E33: 80 | F33: Maintences
A34: 4 | B34: 23/12/2025 | C34: Roti | D34: 4 | E34: 60 | F34: Maintences
A35: 5 | B35: 23/12/2025 | C35: Dall | D35: 1 | E35: 80 | F35: Maintences
A36: 6 | B36: 23/12/2025 | C36: Ch- White Biryani | D36: 1 | E36: 120 | F36: Maintences
A37: 7 | B37: 23/12/2025 | C37: Zeera White Rice | D37: 1 | E37: 100 | F37: Maintences
A38: 8 | B38: 23/12/2025 | C38: Sabzi | D38: 2 | E38: 160 | F38: Maintences
A39: Grand Total Amount | E39: =SUM(E31:E38) -> 795
A41: Preapred By | F41: Clint Signature
A43: SR# | B43: Date | C43: Item Name | D43: QTY | E43: Price | F43: Department
A44: 1 | B44: 23/12/2025 | C44: Ch- White Biryani | D44: 1 | E44: 200 | F44: Maintences
A45: 2 | B45: 23/12/2025 | C45: Ch- Karahi | D45: 1 | E45: 220 | F45: Maintences
A46: 3 | B46: 23/12/2025 | C46: Roti | D46: 5 | E46: 75 | F46: Maintences
A47: 4 | B47: 23/12/2025 | C47: Salad | D47: 1 | E47: 20 | F47: Maintences
A48: Grand Total Amount | E48: =SUM(E44:E47) -> 515
A50: Preapred By | F50: Clint Signature
A52: SR# | B52: Date | C52: Item Name | D52: QTY | E52: Price | F52: Department
...

Sheet Summary Of Farhan Sb Maintenc
A1: SUMMARY OF MAINTENCES DEPART
A2: SR# | B2: Date | C2: Name | D2: Amount | E2: Depart
A3: 1 | B3: 46011 | C3: Farhan Sb | D3: 440 | E3: Maintences
A4: 2 | B4: 46013 | C4: Farhan Sb | D4: 370 | E4: Maintences
A5: 3 | B5: 46013 | C5: Farhan Sb | D5: 670 | E5: Maintences
A6: 4 | B6: 46014 | C6: Farhan Sb | D6: 515 | E6: Maintences
A7: 5 | B7: 46014 | C7: Farhan Sb | D7: 795 | E7: Maintences
A8: 6 | B8: 46015 | C8: Farhan Sb | D8: 945 | E8: Maintences
A9: 7 | B9: 46015 | C9: Farhan Sb | D9: 450 | E9: Maintences
A10: 8 | B10: 46016 | C10: Farhan Sb | D10: 785 | E10: Maintences
A11: 9 | B11: 46020 | C11: Farhan Sb | D11: 335 | E11: Maintences
A12: 10 | B12: 46021 | C12: Farhan Sb | D12: 500 | E12: Maintences
A13: 11 | B13: 46022 | C13: Farhan Sb | D13: 750 | E13: Maintences
A14: Grand Total Amount | D14: =SUM(D3:D13) -> 6555
A16: SUMMARY OF MAINTENCES DEPART
A17: SR# | B17: Date | C17: Name | D17: Amount | E17: Depart
A18: 1 | B18: 46029 | C18: Farhan Sb | D18: 2580 | E18: Maintences
A19: 2 | B19: 46035 | C19: Farhan Sb | D19: 900 | E19: Maintences
A20: 3 | B20: 46037 | C20: Farhan Sb | D20: 620 | E20: Maintences
A21: Grand Total Amount | D21: =SUM(D18:D20) -> 4100
A22: Preapred By | E22: Clint Signature
A27: Admin Sig

Sheet Senior Mess 
A1: LUNCH DYING DEPART | I1: LUNCH DYING DEPART
A2: SR# | B2: Date | C2: Name | D2: Item Name | E2: QTY | F2: Price | G2: Department | I2: SR# | J2: Date | K2: Name | L2: Item Name | M2: QTY | N2: Price | O2: Department
A3: 1 | B3: 16/12/2025 | C3: Daniyal | D3: 4 Karahi, 4 Chawal, 4 Dall,15 Roti | F3: 800+400+320+180 | G3: Dying Depart | I3: 1 | J3: 17/12/2025 | K3: Daniyal | L3: 6 Chicken Qorma+ 18 Roti+ 2 Dahi + Salad | N3: 1200+270+100+40 | O3: Dying Depart
A4: 2 | B4: 16/12/2025 | C4: Azeem | G4: Dying Depart | I4: 2 | J4: 17/12/2025 | K4: Azeem | O4: Dying Depart
A5: 3 | B5: 16/12/2025 | C5: Uaman | G5: Dying Depart | I5: 3 | J5: 17/12/2025 | K5: Uaman | O5: Dying Depart
A6: 4 | B6: 16/12/2025 | C6: Maroof | G6: Dying Depart | I6: 4 | J6: 17/12/2025 | K6: Maroof | O6: Dying Depart
A7: 5 | B7: 16/12/2025 | C7: Nasir | G7: Dying Depart | I7: 5 | J7: 17/12/2025 | K7: Nasir | O7: Dying Depart
A8: 6 | B8: 16/12/2025 | C8: Mueez | G8: Dying Depart | I8: 6 | J8: 17/12/2025 | K8: Mueez | O8: Dying Depart
A9: Grand Total Amount | F9: 1700 | I9: Grand Total Amount | N9: 1610
A11: Preapred By | G11: Clint Signature | I11: Preapred By | O11: Clint Signature
A13: DINNER DYING DEPART | I13: DINNER DYING DEPART
A14: SR# | B14: Date | C14: Name | D14: Item Name | E14: QTY | F14: Price | G14: Department | I14: SR# | J14: Date | K14: Name | L14: Item Name | M14: QTY | N14: Price | O14: Department
A15: 1 | B15: 16/12/2025 | C15: Ali Raza | D15: 3 Sabzi+ 10Roti | F15: 240+150 | G15: Dying Depart | I15: 1 | J15: 17/12/2025 | K15: Daniyal | L15: 1 Sabzi+13 Roti+ 1 Salad | N15: 80+195+20 | O15: Dying Depart
A16: 2 | B16: 16/12/2025 | C16: Azeem | G16: Dying Depart | I16: 2 | J16: 17/12/2025 | K16: Maroof | O16: Dying Depart
A17: 3 | B17: 16/12/2025 | C17: Uaman | G17: Dying Depart | I17: 3 | J17: 17/12/2025 | K17: Yaseen | O17: Dying Depart
A18: Grand Total Amount | F18: 390 | I18: 4 | J18: 17/12/2025 | K18: Ali Raza | O18: Dying Depart
I19: 5 | J19: 17/12/2025 | K19: Azeem | O19: Dying Depart
A20: Preapred By | G20: Clint Signature | O20: Dying Depart
I21: Grand Total Amount | N21: 295
I23: Preapred By | O23: Clint Signature
A27: LUNCH DYING DEPART | I27: DINNER DYING DEPART
A28: SR# | B28: Date | C28: Name | D28: Item Name | E28: QTY | F28: Price | G28: Department | I28: SR# | J28: Date | K28: Name | L28: Item Name | M28: QTY | N28: Price | O28: Department
A29: 1 | B29: 17/12/2025 | C29: Munawar | D29: Chicken Qorma 6+ Roti 15+ Salad 2 Bowl | F29: 1200+225+120 | G29: Dying Depart | I29: 1 | J29: 17/12/2025 | K29: Munawar | L29: Egg 2, Chicken Karahi 4, Chicken Stew 4, Biryani 5, | N29: 50+800+800+900 | O29: Dying Depart
A30: 2 | B30: 17/12/2025 | C30: Waqas | G30: Dying Depart | I30: 2 | J30: 17/12/2025 | K30: Waqas | O30: Dying Depart
A31: 3 | B31: 17/12/2025 | C31: Jhandad | G31: Dying Depart | I31: 3 | J31: 17/12/2025 | K31: Jhandad | O31: Dying Depart
A32: 4 | B32: 17/12/2025 | C32: Rafeeq | G32: Dying Depart | I32: 4 | J32: 17/12/2025 | K32: Rafeeq | O32: Dying Depart
A33: 5 | B33: 17/12/2025 | C33: Shakeel | G33: Dying Depart | I33: 5 | J33: 17/12/2025 | K33: Shakeel | O33: Dying Depart
A34: 6 | B34: 17/12/2025 | C34: Aqaib | G34: Dying Depart | I34: 6 | J34: 17/12/2025 | K34: Aqaib | O34: Dying Depart
A35: Grand Total Amount | F35: =1200+225+120 -> 1545 | I35: Grand Total Amount | N35: =50+800+800+900 -> 2550
A37: Preapred By | G37: Clint Signature | I37: Preapred By | O37: Clint Signature
A43: LUNCH DYING DEPART | I43: DINNER DYING DEPART
A44: SR# | B44: Date | C44: Name | D44: Item Name | E44: QTY | F44: Price | G44: Department | I44: SR# | J44: Date | K44: Name | L44: Item Name | M44: QTY | N44: Price | O44: Department
A45: 1 | B45: 18/12/2025 | C45: Daniyal | D45: Roti 15+ Chicken Stew 3+ Pulao 2+ Biryani 1+ Salad | F45: 225+600+240+180+20 | G45: Dying Depart | I45: 1 | J45: 18/12/2025 | K45: Daniyal | L45: Chicken Karahi 3+ Dall 1+ Roti 18 | N45: 600+80+270 | O45: Dying Depart
A46: 2 | B46: 18/12/2025 | G46: Dying Depart | I46: 2 | J46: 18/12/2025 | O46: Dying Depart
A47: 3 | B47: 18/12/2025 | G47: Dying Depart | I47: 3 | J47: 18/12/2025 | O47: Dying Depart
A48: 4 | B48: 18/12/2025 | G48: Dying Depart | I48: 4 | J48: 18/12/2025 | O48: Dying Depart
A49: 5 | B49: 18/12/2025 | G49: Dying Depart | I49: 5 | J49: 18/12/2025 | O49: Dying Depart
A50: 6 | B50: 18/12/2025 | G50: Dying Depart | I50: 6 | J50: 18/12/2025 | O50: Dying Depart
A51: Grand Total Amount | F51: =225+600+240+180+20 -> 1265 | I51: Grand Total Amount | N51: =600+80+270 -> 950
A53: Preapred By | G53: Clint Signature | I53: Preapred By | O53: Clint Signature
...

Sheet Aqib,waqas,jhandad,rqfeeq Data
A1: LUNCH DYING DEPART
A2: SR# | B2: Date | C2: Name | D2: Item Name | E2: Price | F2: Department
A3: 1 | B3: 46020 | C3: Waqas Sb | D3: Ch- Hara Masala 1+ Salad 1+ Roti 4+ Egg Ghotala 1.5 | E3: 225+20+60+75 | F3: Dying Depart
A4: 2 | B4: 46020 | F4: Dying Depart
A5: 3 | B5: 46020 | F5: Dying Depart
A6: 4 | B6: 46020 | F6: Dying Depart
A7: 5 | B7: 46020 | F7: Dying Depart
A8: Grand Total Amount | E8: =225+20+60+75 -> 380
A9: Preapred By | F9: Clint Signature
A10: LUNCH DYING DEPART
A11: SR# | B11: Date | C11: Name | D11: Item Name | E11: Price | F11: Department
A12: 1 | B12: 46020 | C12: Aqaib Sb | D12: Ch- Hara Masala 1+ Salad 1+ Roti 4+ Egg Ghotala 1.5 | E12: 225+20+60+75 | F12: Dying Depart
A13: 2 | B13: 46020 | F13: Dying Depart
A14: 3 | B14: 46020 | F14: Dying Depart
A15: 4 | B15: 46020 | F15: Dying Depart
A16: 5 | B16: 46020 | F16: Dying Depart
A17: Grand Total Amount | E17: =225+20+60+75 -> 380
A18: Preapred By | F18: Clint Signature
A19: LUNCH DYING DEPART
A20: SR# | B20: Date | C20: Name | D20: Item Name | E20: Price | F20: Department
A21: 1 | B21: 46020 | C21: Jahandad Sb | D21: Ch- Hara Masala 1+ Salad 1+ Roti 4+ Egg Ghotala 1.5 | E21: 225+20+60+75 | F21: Dying Depart
A22: 2 | B22: 46020 | F22: Dying Depart
A23: 3 | B23: 46020 | F23: Dying Depart
A24: 4 | B24: 46020 | F24: Dying Depart
A25: 5 | B25: 46020 | F25: Dying Depart
A26: Grand Total Amount | E26: =225+20+60+75 -> 380
A27: Preapred By | F27: Clint Signature
A28: LUNCH DYING DEPART
A29: SR# | B29: Date | C29: Name | D29: Item Name | E29: Price | F29: Department
A30: 1 | B30: 46020 | C30: Rafeeq Sb | D30: Ch- Hara Masala 1+ Salad 1+ Roti 3+ Egg Ghotala 1.5 | E30: 225+20+45+75 | F30: Dying Depart
A31: 2 | B31: 46020 | F31: Dying Depart
A32: 3 | B32: 46020 | F32: Dying Depart
A33: 4 | B33: 46020 | F33: Dying Depart
A34: 5 | B34: 46020 | F34: Dying Depart
A35: Grand Total Amount | E35: =225+20+45+75 -> 365
A36: Preapred By | F36: Clint Signature
A37: LUNCH DYING DEPART
A38: SR# | B38: Date | C38: Name | D38: Item Name | E38: Price | F38: Department
A39: 1 | B39: 46021 | C39: Waqas Sb | D39: Dahi+ Salad+ Ch- Pulao | E39: 100+50+250 | F39: Dying Depart
A40: 2 | B40: 46021 | F40: Dying Depart
...

Sheet Aqib,Waqas,Jhandad,Rafeeq Sumry
A1: SUMMARY
A2: SR# | B2: Date | C2: Name | D2: Amount | E2: Signature | F2: Received Amount Date
A3: 1 | B3: 17 Dec to 31 Dec 2025 | C3: Waqas Sb | D3: =3892.5+D12 -> 4857.5
A4: 2 | B4: 17 Dec to 31 Dec 2025 | C4: Jhandad Sb | D4: =3893.5+D14 -> 4858.5
A5: 3 | B5: 17 Dec to 31 Dec 2025 | C5: Rafeeq Sb | D5: =3894.5+D15 -> 4829.5
A6: 4 | B6: 17 Dec to 31 Dec 2025 | C6: Aqaib Sb | D6: =3895.5+D13 -> 4860.5
A7: Total Amount | D7: =SUM(D3:D6) -> 19406
A8: Preapred BY | F8: Clint Signature
A10: SUMMARY | H10: SUMMARY
A11: SR# | B11: Date | C11: Name | D11: Amount | E11: Signature | F11: Received Amount Date | H11: SR# | I11: Date | J11: Name | K11: Amount | L11: Signature | M11: Received Amount Date
A12: 1 | B12: 29Dec to 31 Dec 2025 | C12: Waqas Sb | D12: ='Aqib,waqas,jhandad,rqfeeq Data'!E8+'Aqib,waqas,jhandad,rqfeeq Data'!E44+'Aqib,waqas,jhandad,rqfeeq Data'!E80 -> 965 | H12: 1 | I12: 17 Dec 2025 to 15 Jan 2026 | J12: Waqas Sb | K12: =D3+D12+D20+D28+D41+D50+D59+D67+D75+D81+D89+D97+D105 -> 9588
A13: 2 | B13: 29Dec to 31 Dec 2025 | C13: Aqaib Sb | D13: ='Aqib,waqas,jhandad,rqfeeq Data'!E17+'Aqib,waqas,jhandad,rqfeeq Data'!E53+'Aqib,waqas,jhandad,rqfeeq Data'!E89 -> 965 | H13: 2 | I13: 17 Dec 2025 to 15 Jan 2026 | J13: Jhandad Sb | K13: =D4+D14+D22+D30+D44+D52+D60+D69+D76+D83+D90 -> 9861
A14: 3 | B14: 29Dec to 31 Dec 2025 | C14: Jhandad Sb | D14: ='Aqib,waqas,jhandad,rqfeeq Data'!E26+'Aqib,waqas,jhandad,rqfeeq Data'!E62+'Aqib,waqas,jhandad,rqfeeq Data'!E98 -> 965 | H14: 3 | I14: 17 Dec 2025 to 15 Jan 2026 | J14: Rafeeq Sb | K14: =D5+D15+D23+D31+D45+D51+D68+D82+D98+D106 -> 8728
A15: 4 | B15: 29Dec to 31 Dec 2025 | C15: Rafeeq Sb | D15: ='Aqib,waqas,jhandad,rqfeeq Data'!E35+'Aqib,waqas,jhandad,rqfeeq Data'!E71+'Aqib,waqas,jhandad,rqfeeq Data'!E107 -> 935 | H15: 4 | I15: 17 Dec 2025 to 15 Jan 2026 | J15: Aqaib Sb | K15: =D6+D13+D21+D29+D36+D42+D43+D53+D61+D70+D84+D91 -> 9524.5
A16: Total Amount | D16: =SUM(D12:D15) -> 3830 | H16: 5 | I16: 17 Dec 2025 to 15 Jan 2026 | J16: Shakeel Sb | K16: =D54 -> 370
H17: 6 | I17: 46036 | J17: Munawar Sb | K17: 100
A18: SUMMARY | H18: Total Amount | K18: =SUM(K12:K17) -> 38171.5
A19: SR# | B19: Date | C19: Name | D19: Amount | E19: Signature | F19: Received Amount Date | H19: Preapred BY | M19: Clint Signature
A20: 1 | B20: 46024 | C20: Waqas Sb | D20: 470
A21: 2 | B21: 46024 | C21: Aqaib Sb | D21: =470+120 -> 590
A22: 3 | B22: 46024 | C22: Jhandad Sb | D22: 470
A23: 4 | B23: 46024 | C23: Rafeeq Sb | D23: 470
A24: Total Amount | D24: =SUM(D20:D23) -> 2000
A26: SUMMARY
A27: SR# | B27: Date | C27: Name | D27: Amount | E27: Signature | F27: Received Amount Date
A28: 1 | B28: 46025 | C28: Waqas Sb | D28: 428
A29: 2 | B29: 46025 | C29: Aqaib Sb | D29: 428
A30: 3 | B30: 46025 | C30: Jhandad Sb | D30: 428
A31: 4 | B31: 46025 | C31: Rafeeq Sb | D31: 428
A32: Total Amount | D32: =SUM(D28:D31) -> 1712
A34: SUMMARY
A35: SR# | B35: Date | C35: Name | D35: Amount | E35: Signature | F35: Received Amount Date
A36: 1 | B36: 46026 | C36: Aqaib Sb | D36: =260+195 -> 455
A37: Total Amount | D37: =SUM(D36:D36) -> 455
A39: SUMMARY
A40: SR# | B40: Date | C40: Name | D40: Amount | E40: Signature | F40: Received Amount Date
A41: 1 | B41: 46027 | C41: Waqas Sb | D41: 310
A42: 2 | B42: 46027 | C42: Aqaib Sb | D42: 311
B43: 46027 | C43: Aqaib Sb | D43: 225
A44: 3 | B44: 46027 | C44: Jhandad Sb | D44: 312
...

Sheet Daniyal Meal Data 
A1: LUNCH DYING DEPART
A2: SR# | B2: Date | C2: Name | D2: Item Name | E2: QTY | F2: Price | G2: Department
A3: 1 | B3: 16/12/2025 | C3: Daniyal | D3: 4 Karahi, 4 Chawal, 4 Dall,15 Roti | F3: 800+400+320+180 | G3: Dying Depart
A4: 2 | B4: 16/12/2025 | C4: Azeem | G4: Dying Depart
A5: 3 | B5: 16/12/2025 | C5: Uaman | G5: Dying Depart
A6: 4 | B6: 16/12/2025 | C6: Maroof | G6: Dying Depart
A7: 5 | B7: 16/12/2025 | C7: Nasir | G7: Dying Depart
A8: 6 | B8: 16/12/2025 | C8: Mueez | G8: Dying Depart
A9: Grand Total Amount | F9: 1700
A11: Preapred By | G11: Clint Signature
A13: LUNCH DYING DEPART
A14: SR# | B14: Date | C14: Name | D14: Item Name | E14: QTY | F14: Price | G14: Department
A15: 1 | B15: 17/12/2025 | C15: Daniyal | D15: 6 Chicken Qorma+ 18 Roti+ 2 Dahi + Salad | F15: 1200+270+100+40 | G15: Dying Depart
A16: 2 | B16: 17/12/2025 | C16: Azeem | G16: Dying Depart
A17: 3 | B17: 17/12/2025 | C17: Uaman | G17: Dying Depart
A18: 4 | B18: 17/12/2025 | C18: Maroof | G18: Dying Depart
A19: 5 | B19: 17/12/2025 | C19: Nasir | G19: Dying Depart
A20: 6 | B20: 17/12/2025 | C20: Mueez | G20: Dying Depart
A21: Grand Total Amount | F21: 1610
A23: Preapred By | G23: Clint Signature
A25: DINNER DYING DEPART
A26: SR# | B26: Date | C26: Name | D26: Item Name | E26: QTY | F26: Price | G26: Department
A27: 1 | B27: 17/12/2025 | C27: Daniyal | D27: 1 Sabzi+13 Roti+ 1 Salad | F27: 80+195+20 | G27: Dying Depart
A28: 2 | B28: 17/12/2025 | C28: Maroof | G28: Dying Depart
A29: 3 | B29: 17/12/2025 | C29: Yaseen | G29: Dying Depart
A30: 4 | B30: 17/12/2025 | C30: Ali Raza | G30: Dying Depart
A31: 5 | B31: 17/12/2025 | C31: Azeem | G31: Dying Depart
G32: Dying Depart
A33: Grand Total Amount | F33: 295
A35: Preapred By | G35: Clint Signature
A37: LUNCH DYING DEPART
A38: SR# | B38: Date | C38: Name | D38: Item Name | E38: QTY | F38: Price | G38: Department
A39: 1 | B39: 18/12/2025 | C39: Daniyal | D39: Roti 15+ Chicken Stew 3+ Pulao 2+ Biryani 1+ Salad | F39: 225+600+240+180+20 | G39: Dying Depart
A40: 2 | B40: 18/12/2025 | G40: Dying Depart
A41: 3 | B41: 18/12/2025 | G41: Dying Depart
A42: 4 | B42: 18/12/2025 | G42: Dying Depart
A43: 5 | B43: 18/12/2025 | G43: Dying Depart
A44: 6 | B44: 18/12/2025 | G44: Dying Depart
A45: Grand Total Amount | F45: =225+600+240+180+20 -> 1265
A47: Preapred By | G47: Clint Signature
...

Sheet Daniyal Summary Daying Dept
A1: Mujtaba And Brothers (Canteen Bill)
A2: SR# | B2: Date | C2: Name | D2: Amount | E2: Signature | F2: Received Amount Date | G2: Received Amount | H2: Balance Amount
