Workbook

Sheet Sheet1
A2: 1 cup flour | B2: 120 grams | C2: 4.2 oz | D2: Medium Onion | E2: 150-170 Grams
A3: 1 cup whole wheat flour | B3: 130 grams | C3: 4.6 oz | D3: Small Onion | E3: 125 grams
A4: 1 cup almond flour | B4: 112 grams | C4: 3.9 oz | D4: Tomato Large | E4: 180 grams
A5: 1 cup whole milk | B5: 240 grams | C5: 8.6 oz | D5: Tomato Medium | E5: 120 grams
A6: 1 cup Oil | B6: 225 grams | D6: Tomato Small | E6: 90 grams
A7: 1 Cup Chopped Onion | B7: 52 grams | D7: Potato Medium | E7: 150 grams
A8: 1 Cup Chickpeas | B8: 166 grams | D8: Cucumber 1 pcs | E8: 300 grams
A9: 1 Cup Raw Rice | B9: 200 grams | D9: Garlic Clove | E9: 14 grams
A10: 1 cup Yogurt | B10: 240 grams | C10: 8.6 oz | D10: Chicken Breast Weight | E10: 174 grams | F10: =0.174*3 -> 0.522
A11: 1 cup sugar | B11: 200 grams | C11: 7.1 oz | D11: Bell Pepper 1 Pcs | E11: 130 grams
A12: 1 cup Vinegar | B12: 230 grams | D12: Butter Tablespoon | E12: 14 grams
A13: 1 Cup Cheese Cheddar | B13: 120 grams | D13: Carrot Small | E13: 54 grams
A14: 1 Cup Mayonnaise | B14: 230 grams
A15: 1 Cup Spring Onion | B15: 104 grams
A16: 1 Cup Vermicelli | B16: 230 grams
A17: 1 Cup Lemon Juice | B17: 230 grams
A18: 1 cup Butter | B18: 240 grams
A19: 1 cup Olives | B19: 180 grams
A20: 1 cup brown sugar | B20: 220 grams | C20: 7.8 oz
A21: 1 cup powdered sugar | B21: 115 grams | C21: 4.1 oz
A22: Honey | B22: 340 grams
A23: 1 cup oatmeal | B23: 100 grams | C23: 3.6 oz
A25: Cup | B25: Fluid Ounce | C25: TBSP | D25: TSP | E25: Milliliter
A26: 1 cup | B26: 8 oz | C26: 16 Tbsp | D26: 48 tsp | E26: 237 ml
A27: 3/4 cup | B27: 6 oz | C27: 12 Tbsp | D27: 36 tsp | E27: 177 ml
A28: 2/3 cup | B28: 5 1/3 oz | C28: 10.6 Tbsp | D28: 32 tsp | E28: 158 ml
A29: 1/2 cup | B29: 4 oz | C29: 8 Tbsp | D29: 24 tsp | E29: 118 ml
A30: 1/3 cup | B30: 2 2/3 oz | C30: 5.3 Tbsp | D30: 16 tsp | E30: 79 ml
A31: 1/4 cup | B31: 2 oz | C31: 4 Tbsp | D31: 12 tsp | E31: 59 ml
A32: 1/8 cup | B32: 1 oz | C32: 2 Tbsp | D32: 6 tsp | E32: 30 ml
A33: 1/16 cup | B33: 1/2 oz | C33: 1 Tbsp | D33: 3 tsp | E33: 15 ml

Sheet Recipes
A1: Recipes Consolidate
A2: Dish Name | B2: Dish Category | C2: Dish Type | D2: Ingredients | E2: Qty | F2: UOM | G2: BBQ Rates | H2: Amount | I2: Dish UOM | J2: Meat Type | K2: Site Rates | L2: Amount
A3: Achar | B3: Chatni & Sauces | C3: Achar | D3: Apple Vinegar | E3: 0.012 | F3: KG | G3: 480 | H3: =G3*E3 -> 5.76 | I3: Kg | J3: 0 | K3: =VLOOKUP(D3,Ingredients!C:G,4,0) -> 500 | L3: =K3*E3 -> 6
A4: Achar | B4: Chatni & Sauces | C4: Achar | D4: Mint (Podina) | E4: 0.01 | F4: KG | G4: 8 | H4: =G4*E4 -> 0.08 | I4: Kg | J4: 0 | K4: =VLOOKUP(D4,Ingredients!C:G,5,0) -> 6 | L4: =K4*E4 -> 0.06
A5: Achar | B5: Chatni & Sauces | C5: Achar | D5: RED CHILLI CRUSH | E5: 0.006 | F5: KG | G5: 1000 | H5: =G5*E5 -> 6 | I5: Kg | J5: 0 | K5: =VLOOKUP(D5,Ingredients!C:G,5,0) -> 950 | L5: =K5*E5 -> 5.7
A6: Achar | B6: Chatni & Sauces | C6: Achar | D6: CARAWAY SEED (KALONJI) | E6: 0.01 | F6: KG | G6: 700 | H6: =G6*E6 -> 7 | I6: Kg | J6: 0 | K6: =VLOOKUP(D6,Ingredients!C:G,5,0) -> 700 | L6: =K6*E6 -> 7
A7: Achar | B7: Chatni & Sauces | C7: Achar | D7: SUGAR | E7: 0.1 | F7: KG | G7: 149 | H7: =G7*E7 -> 14.9 | I7: Kg | J7: 0 | K7: =VLOOKUP(D7,Ingredients!C:G,5,0) -> 123 | L7: =K7*E7 -> 12.3
A8: Achar | B8: Chatni & Sauces | C8: Achar | D8: Kukree | E8: 0.1 | F8: KG | G8: 60 | H8: =G8*E8 -> 6 | I8: Kg | J8: 0 | K8: =VLOOKUP(D8,Ingredients!C:G,5,0) -> 120 | L8: =K8*E8 -> 12
A9: Achar | B9: Chatni & Sauces | C9: Achar | D9: Cauliflower (Phool Gobi) | E9: 0.1 | F9: KG | G9: 140 | H9: =G9*E9 -> 14 | I9: Kg | J9: 0 | K9: =VLOOKUP(D9,Ingredients!C:G,5,0) -> 200 | L9: =K9*E9 -> 20
A10: Achar | B10: Chatni & Sauces | C10: Achar | D10: Brinjal (Bengan) | E10: 0.1 | F10: KG | G10: 30 | H10: =G10*E10 -> 3 | I10: Kg | J10: 0 | K10: =VLOOKUP(D10,Ingredients!C:G,5,0) -> 60 | L10: =K10*E10 -> 6
A11: Achar | B11: Chatni & Sauces | C11: Achar | D11: Cucumber (Kheera) | E11: 0.1 | F11: KG | G11: 120 | H11: =G11*E11 -> 12 | I11: Kg | J11: 0 | K11: =VLOOKUP(D11,Ingredients!C:G,5,0) -> 60 | L11: =K11*E11 -> 6
A12: Achar | B12: Chatni & Sauces | C12: Achar | D12: Carrot | E12: 0.1 | F12: KG | G12: 130 | H12: =G12*E12 -> 13 | I12: Kg | J12: 0 | K12: =VLOOKUP(D12,Ingredients!C:G,5,0) -> 90 | L12: =K12*E12 -> 9
A13: Achar | B13: Chatni & Sauces | C13: Achar | D13: Garlic (Lehsan) | E13: 0.1 | F13: KG | G13: 270 | H13: =G13*E13 -> 27 | I13: Kg | J13: 0 | K13: =VLOOKUP(D13,Ingredients!C:G,5,0) -> 310 | L13: =K13*E13 -> 31
A14: Achar | B14: Chatni & Sauces | C14: Achar | D14: Radish (Mooli) | E14: 0.1 | F14: KG | G14: 80 | H14: =G14*E14 -> 8 | I14: Kg | J14: 0 | K14: =VLOOKUP(D14,Ingredients!C:G,5,0) -> 5 | L14: =K14*E14 -> 0.5
A15: Achar | B15: Chatni & Sauces | C15: Achar | D15: Turnip | E15: 0.1 | F15: KG | G15: 100 | H15: =G15*E15 -> 10 | I15: Kg | J15: 0 | K15: =VLOOKUP(D15,Ingredients!C:G,5,0) -> 100 | L15: =K15*E15 -> 10
A16: Afghani Chicken Boti | B16: Main Course | C16: BBQ | D16: MILK CREAM 200ML | E16: 0.2 | F16: KG | G16: 177 | H16: =G16*E16 -> 35.4 | I16: Kg | J16: Chicken Boneless | K16: =VLOOKUP(D16,Ingredients!C:G,5,0) -> 920 | L16: =K16*E16 -> 184
A17: Afghani Chicken Boti | B17: Main Course | C17: BBQ | D17: COOKING OIL 16LTR | E17: 0.057142857 | F17: Litre | G17: 520.63 | H17: =G17*E17 -> 29.750286 | I17: Kg | J17: Chicken Boneless | K17: 550 | L17: =K17*E17 -> 31.428571
A18: Afghani Chicken Boti | B18: Main Course | C18: BBQ | D18: COOKING SALT 800GM | E18: 0.014285714 | F18: KG | G18: 30 | H18: =G18*E18 -> 0.42857143 | I18: Kg | J18: Chicken Boneless | K18: =VLOOKUP(D18,Ingredients!C:G,5,0) -> 55 | L18: =K18*E18 -> 0.78571429
A19: Afghani Chicken Boti | B19: Main Course | C19: BBQ | D19: Garlic (Lehsan) | E19: 0.085714286 | F19: KG | G19: 270 | H19: =G19*E19 -> 23.142857 | I19: Kg | J19: Chicken Boneless | K19: =VLOOKUP(D19,Ingredients!C:G,5,0) -> 310 | L19: =K19*E19 -> 26.571429
A20: Afghani Chicken Boti | B20: Main Course | C20: BBQ | D20: Ginger (Adrak) | E20: 0.057142857 | F20: KG | G20: 740 | H20: =G20*E20 -> 42.285714 | I20: Kg | J20: Chicken Boneless | K20: =VLOOKUP(D20,Ingredients!C:G,5,0) -> 780 | L20: =K20*E20 -> 44.571429
A21: Afghani Chicken Boti | B21: Main Course | C21: BBQ | D21: CHICKEN BONELESS | E21: 1 | F21: KG | G21: 908 | H21: =G21*E21 -> 908 | I21: Kg | J21: Chicken Boneless | K21: =VLOOKUP(D21,Ingredients!C:G,5,0) -> 908 | L21: =K21*E21 -> 908
A22: Beef Chapli Kabab | B22: Main Course | C22: Fried | D22: EGGS | E22: 2.5 | F22: (Pcs) | G22: 24.64 | H22: =G22*E22 -> 61.6 | I22: Kg | J22: Beef Boneless | K22: =VLOOKUP(D22,Ingredients!C:G,5,0) -> 20.06 | L22: =K22*E22 -> 50.15
A23: Beef Chapli Kabab | B23: Main Course | C23: Fried | D23: COOKING SALT 800GM | E23: 0.0125 | F23: KG | G23: 30 | H23: =G23*E23 -> 0.375 | I23: Kg | J23: Beef Boneless | K23: =VLOOKUP(D23,Ingredients!C:G,5,0) -> 55 | L23: =K23*E23 -> 0.6875
A24: Beef Chapli Kabab | B24: Main Course | C24: Fried | D24: SWEET SODA | E24: 0.015 | F24: KG | G24: 128 | H24: =G24*E24 -> 1.92 | I24: Kg | J24: Beef Boneless | K24: =VLOOKUP(D24,Ingredients!C:G,5,0) -> 131.2 | L24: =K24*E24 -> 1.968
A25: Beef Chapli Kabab | B25: Main Course | C25: Fried | D25: Tomato | E25: 0.025 | F25: KG | G25: 85 | H25: =G25*E25 -> 2.125 | I25: Kg | J25: Beef Boneless | K25: =VLOOKUP(D25,Ingredients!C:G,5,0) -> 70 | L25: =K25*E25 -> 1.75
A26: Beef Chapli Kabab | B26: Main Course | C26: Fried | D26: Onion (Piyaz) | E26: 0.05 | F26: KG | G26: 55 | H26: =G26*E26 -> 2.75 | I26: Kg | J26: Beef Boneless | K26: =VLOOKUP(D26,Ingredients!C:G,5,0) -> 80 | L26: =K26*E26 -> 4
A27: Beef Chapli Kabab | B27: Main Course | C27: Fried | D27: Green Chilli (Hari Mirch) | E27: 0.0125 | F27: KG | G27: 60 | H27: =G27*E27 -> 0.75 | I27: Kg | J27: Beef Boneless | K27: =VLOOKUP(D27,Ingredients!C:G,5,0) -> 100 | L27: =K27*E27 -> 1.25
A28: Beef Chapli Kabab | B28: Main Course | C28: Fried | D28: Makai Ata White | E28: 0.0125 | F28: KG | G28: 200 | H28: =G28*E28 -> 2.5 | I28: Kg | J28: Beef Boneless | K28: =VLOOKUP(D28,Ingredients!C:G,5,0) -> 200 | L28: =K28*E28 -> 2.5
A29: Beef Chapli Kabab | B29: Main Course | C29: Fried | D29: Amchoor Powder. | E29: 0.0125 | F29: KG | G29: 200 | H29: =G29*E29 -> 2.5 | I29: Kg | J29: Beef Boneless | K29: =VLOOKUP(D29,Ingredients!C:G,5,0) -> 350 | L29: =K29*E29 -> 4.375
... A77: Chicken Cheese Kabab | B77: Main Course | C77: Fried | D77: CORIANDER WHOLE | E77: 0.016 | F77: KG | G77: 440 | H77: =G77*E77 -> 7.04 | I77: Kg | J77: Chicken Boneless | K77: =VLOOKUP(D77,Ingredients!C:G,5,0) -> 450 | L77: =K77*E77 -> 7.2
A78: Chicken Cheese Kabab | B78: Main Course | C78: Fried | D78: CHEESE CHEDDAR 2KG | E78: 0.16 | F78: KG | G78: 612.035 | H78: =G78*E78 -> 97.9256 | I78: Kg | J78: Chicken Boneless | K78: =VLOOKUP(D78,Ingredients!C:F,3,0) -> 1500 | L78: =K78*E78 -> 240
A79: Chicken Cheese Kabab | B79: Main Course | C79: Fried | D79: COOKING SALT 800GM | E79: 0.02 | F79: KG | G79: 30 | H79: =G79*E79 -> 0.6 | I79: Kg | J79: Chicken Boneless | K79: =VLOOKUP(D79,Ingredients!C:G,5,0) -> 55 | L79: =K79*E79 -> 1.1
A80: Chicken Cheese Kabab | B80: Main Course | C80: Fried | D80: Onion (Piyaz) | E80: 0.04 | F80: KG | G80: 55 | H80: =G80*E80 -> 2.2 | I80: Kg | J80: Chicken Boneless | K80: =VLOOKUP(D80,Ingredients!C:G,5,0) -> 80 | L80: =K80*E80 -> 3.2
A81: Chicken Cheese Kabab | B81: Main Course | C81: Fried | D81: Green Chilli (Hari Mirch) | E81: 0.08 | F81: KG | G81: 60 | H81: =G81*E81 -> 4.8 | I81: Kg | J81: Chicken Boneless | K81: =VLOOKUP(D81,Ingredients!C:G,5,0) -> 100 | L81: =K81*E81 -> 8
A82: Chicken Cheese Kabab | B82: Main Course | C82: Fried | D82: FAT (CHARBI) | E82: 0.14 | F82: KG | G82: 500 | H82: =G82*E82 -> 70 | I82: Kg | J82: Chicken Boneless | K82: =VLOOKUP(D82,Ingredients!C:G,5,0) -> 500 | L82: =K82*E82 -> 70
A83: Chicken Cheese Kabab | B83: Main Course | C83: Fried | D83: CHICKEN BONELESS | E83: 1 | F83: KG | G83: 908 | H83: =G83*E83 -> 908 | I83: Kg | J83: Chicken Boneless | K83: =VLOOKUP(D83,Ingredients!C:G,5,0) -> 908 | L83: =K83*E83 -> 908
A84: Chicken Behari | B84: Main Course | C84: BBQ | D84: KACHRI PWD | E84: 0.0125 | F84: KG | G84: 650 | H84: =G84*E84 -> 8.125 | I84: Kg | J84: Chicken Bone In | K84: =VLOOKUP(D84,Ingredients!C:G,5,0) -> 700 | L84: =K84*E84 -> 8.75
A85: Chicken Behari | B85: Main Course | C85: BBQ | D85: COOKING OIL 16LTR | E85: 0.15 | F85: Litre | G85: 520.63 | H85: =G85*E85 -> 78.0945 | I85: Kg | J85: Chicken Bone In | K85: 550 | L85: =K85*E85 -> 82.5
A86: Chicken Behari | B86: Main Course | C86: BBQ | D86: Coriander (Dhanya) | E86: 0.0125 | F86: KG | G86: 13 | H86: =G86*E86 -> 0.1625 | I86: Kg | J86: Chicken Bone In | K86: =VLOOKUP(D86,Ingredients!C:G,5,0) -> 15 | L86: =K86*E86 -> 0.1875
A87: Chicken Behari | B87: Main Course | C87: BBQ | D87: Ajwaen | E87: 0.01 | F87: KG | G87: 350 | H87: =G87*E87 -> 3.5 | I87: Kg | J87: Chicken Bone In | K87: =VLOOKUP(D87,Ingredients!C:G,5,0) -> 457.875 | L87: =K87*E87 -> 4.57875
...

Sheet Consolidate
G1: BBQ Rates | K1: Site Rates
A2: S. # | B2: Dish Name | C2: Dish Category | D2: Dish Type | E2: Meat Type | F2: Dish UOM | G2: BBQ Rates | H2: Meat Rates | I2: Making KHI | K2: Site Rates | L2: Meat Rates | M2: Making KHI
A3: 1 | B3: Achar | C3: =VLOOKUP(B3,Recipes!A:B,2,0) -> Chatni & Sauces | D3: =VLOOKUP(B3,Recipes!A:C,3,0) -> Achar | E3: =VLOOKUP(B3,Recipes!A:J,10,0) -> 0 | F3: =VLOOKUP(B3,Recipes!A:I,9,0) -> Kg | G3: =SUMIF(Recipes!A:A,Consolidate!B3,Recipes!H:H) -> 126.74 | H3: =SUMIFS(Recipes!$H:$H,Recipes!$D:$D,Consolidate!$E3,Recipes!$A:$A,Consolidate!$B3) -> 0 | I3: =G3-H3 -> 126.74 | K3: =SUMIF(Recipes!A:A,Consolidate!B3,Recipes!L:L) -> 125.56 | L3: =SUMIFS(Recipes!$L:$L,Recipes!$D:$D,Consolidate!$E3,Recipes!$A:$A,Consolidate!$B3) -> 0 | M3: =K3-L3 -> 125.56
A4: =A3+1 -> 2 | B4: Achar Kg | C4: =VLOOKUP(B4,Recipes!A:B,2,0) -> Chatni & Sauces | D4: =VLOOKUP(B4,Recipes!A:C,3,0) -> Achar Kg | E4: =VLOOKUP(B4,Recipes!A:J,10,0) -> 0 | F4: =VLOOKUP(B4,Recipes!A:I,9,0) -> Kg | G4: =SUMIF(Recipes!A:A,Consolidate!B4,Recipes!H:H) -> 450 | H4: =SUMIFS(Recipes!$H:$H,Recipes!$D:$D,Consolidate!$E4,Recipes!$A:$A,Consolidate!$B4) -> 0 | I4: =G4-H4 -> 450 | K4: =SUMIF(Recipes!A:A,Consolidate!B4,Recipes!L:L) -> 450 | L4: =SUMIFS(Recipes!$L:$L,Recipes!$D:$D,Consolidate!$E4,Recipes!$A:$A,Consolidate!$B4) -> 0 | M4: =K4-L4 -> 450
A5: =A4+1 -> 3 | B5: Afghani Chicken Boti | C5: =VLOOKUP(B5,Recipes!A:B,2,0) -> Main Course | D5: =VLOOKUP(B5,Recipes!A:C,3,0) -> BBQ | E5: =VLOOKUP(B5,Recipes!A:J,10,0) -> Chicken Boneless | F5: =VLOOKUP(B5,Recipes!A:I,9,0) -> Kg | G5: =SUMIF(Recipes!A:A,Consolidate!B5,Recipes!H:H) -> 1039.0074 | H5: =SUMIFS(Recipes!$H:$H,Recipes!$D:$D,Consolidate!$E5,Recipes!$A:$A,Consolidate!$B5) -> 908 | I5: =G5-H5 -> 131.00743 | K5: =SUMIF(Recipes!A:A,Consolidate!B5,Recipes!L:L) -> 1195.3571 | L5: =SUMIFS(Recipes!$L:$L,Recipes!$D:$D,Consolidate!$E5,Recipes!$A:$A,Consolidate!$B5) -> 908 | M5: =K5-L5 -> 287.35714
A6: =A5+1 -> 4 | B6: Alfredo Pasta | C6: =VLOOKUP(B6,Recipes!A:B,2,0) -> Side Dish | D6: =VLOOKUP(B6,Recipes!A:C,3,0) -> Gravy | E6: =VLOOKUP(B6,Recipes!A:J,10,0) -> 0 | F6: =VLOOKUP(B6,Recipes!A:I,9,0) -> Kg | G6: =SUMIF(Recipes!A:A,Consolidate!B6,Recipes!H:H) -> 1534.6722 | H6: =SUMIFS(Recipes!$H:$H,Recipes!$D:$D,Consolidate!$E6,Recipes!$A:$A,Consolidate!$B6) -> 0 | I6: =G6-H6 -> 1534.6722 | K6: =SUMIF(Recipes!A:A,Consolidate!B6,Recipes!L:L) -> 2506.8978 | L6: =SUMIFS(Recipes!$L:$L,Recipes!$D:$D,Consolidate!$E6,Recipes!$A:$A,Consolidate!$B6) -> 0 | M6: =K6-L6 -> 2506.8978
A7: =A6+1 -> 5 | B7: Aloo Bhujia | C7: =VLOOKUP(B7,Recipes!A:B,2,0) -> Side Dish | D7: =VLOOKUP(B7,Recipes!A:C,3,0) -> Dry | E7: =VLOOKUP(B7,Recipes!A:J,10,0) -> 0 | F7: =VLOOKUP(B7,Recipes!A:I,9,0) -> Kg | G7: =SUMIF(Recipes!A:A,Consolidate!B7,Recipes!H:H) -> 144.8415 | H7: =SUMIFS(Recipes!$H:$H,Recipes!$D:$D,Consolidate!$E7,Recipes!$A:$A,Consolidate!$B7) -> 0 | I7: =G7-H7 -> 144.8415 | K7: =SUMIF(Recipes!A:A,Consolidate!B7,Recipes!L:L) -> 158.31 | L7: =SUMIFS(Recipes!$L:$L,Recipes!$D:$D,Consolidate!$E7,Recipes!$A:$A,Consolidate!$B7) -> 0 | M7: =K7-L7 -> 158.31
A8: =A7+1 -> 6 | B8: Aloo Chana Tarkari | C8: =VLOOKUP(B8,Recipes!A:B,2,0) -> Side Dish | D8: =VLOOKUP(B8,Recipes!A:C,3,0) -> Daal / Chana | E8: =VLOOKUP(B8,Recipes!A:J,10,0) -> 0 | F8: =VLOOKUP(B8,Recipes!A:I,9,0) -> 5 Pax | G8: =SUMIF(Recipes!A:A,Consolidate!B8,Recipes!H:H) -> 119.30575 | H8: =SUMIFS(Recipes!$H:$H,Recipes!$D:$D,Consolidate!$E8,Recipes!$A:$A,Consolidate!$B8) -> 0 | I8: =G8-H8 -> 119.30575 | K8: =SUMIF(Recipes!A:A,Consolidate!B8,Recipes!L:L) -> 149.62 | L8: =SUMIFS(Recipes!$L:$L,Recipes!$D:$D,Consolidate!$E8,Recipes!$A:$A,Consolidate!$B8) -> 0 | M8: =K8-L8 -> 149.62
A9: =A8+1 -> 7 | B9: Aloo Ka Paratha | C9: =VLOOKUP(B9,Recipes!A:B,2,0) -> Roti & Paratha | D9: =VLOOKUP(B9,Recipes!A:C,3,0) -> Aloo Paratha | E9: =VLOOKUP(B9,Recipes!A:J,10,0) -> 0 | F9: =VLOOKUP(B9,Recipes!A:I,9,0) -> Pcs | G9: =SUMIF(Recipes!A:A,Consolidate!B9,Recipes!H:H) -> 34.18817 | H9: =SUMIFS(Recipes!$H:$H,Recipes!$D:$D,Consolidate!$E9,Recipes!$A:$A,Consolidate!$B9) -> 0 | I9: =G9-H9 -> 34.18817 | K9: =SUMIF(Recipes!A:A,Consolidate!B9,Recipes!L:L) -> 36.1815 | L9: =SUMIFS(Recipes!$L:$L,Recipes!$D:$D,Consolidate!$E9,Recipes!$A:$A,Consolidate!$B9) -> 0 | M9: =K9-L9 -> 36.1815
A10: =A9+1 -> 8 | B10: Aloo Ki Tarkaari | C10: =VLOOKUP(B10,Recipes!A:B,2,0) -> Side Dish | D10: =VLOOKUP(B10,Recipes!A:C,3,0) -> Gravy | E10: =VLOOKUP(B10,Recipes!A:J,10,0) -> 0 | F10: =VLOOKUP(B10,Recipes!A:I,9,0) -> Kg | G10: =SUMIF(Recipes!A:A,Consolidate!B10,Recipes!H:H) -> 295.8134 | H10: =SUMIFS(Recipes!$H:$H,Recipes!$D:$D,Consolidate!$E10,Recipes!$A:$A,Consolidate!$B10) -> 0 | I10: =G10-H10 -> 295.8134 | K10: =SUMIF(Recipes!A:A,Consolidate!B10,Recipes!L:L) -> 311.55 | L10: =SUMIFS(Recipes!$L:$L,Recipes!$D:$D,Consolidate!$E10,Recipes!$A:$A,Consolidate!$B10) -> 0 | M10: =K10-L10 -> 311.55
A11: =A10+1 -> 9 | B11: Aloo Matar Pulao | C11: =VLOOKUP(B11,Recipes!A:B,2,0) -> Side Dish | D11: =VLOOKUP(B11,Recipes!A:C,3,0) -> Rice | E11: =VLOOKUP(B11,Recipes!A:J,10,0) -> 0 | F11: =VLOOKUP(B11,Recipes!A:I,9,0) -> Kg | G11: =SUMIF(Recipes!A:A,Consolidate!B11,Recipes!H:H) -> 850.413 | H11: =SUMIFS(Recipes!$H:$H,Recipes!$D:$D,Consolidate!$E11,Recipes!$A:$A,Consolidate!$B11) -> 0 | I11: =G11-H11 -> 850.413 | K11: =SUMIF(Recipes!A:A,Consolidate!B11,Recipes!L:L) -> 822.425 | L11: =SUMIFS(Recipes!$L:$L,Recipes!$D:$D,Consolidate!$E11,Recipes!$A:$A,Consolidate!$B11) -> 0 | M11: =K11-L11 -> 822.425
A12: =A11+1 -> 10 | B12: Aloo Palak | C12: =VLOOKUP(B12,Recipes!A:B,2,0) -> Side Dish | D12: =VLOOKUP(B12,Recipes!A:C,3,0) -> Dry | E12: =VLOOKUP(B12,Recipes!A:J,10,0) -> 0 | F12: =VLOOKUP(B12,Recipes!A:I,9,0) -> Kg | G12: =SUMIF(Recipes!A:A,Consolidate!B12,Recipes!H:H) -> 316.52108 | H12: =SUMIFS(Recipes!$H:$H,Recipes!$D:$D,Consolidate!$E12,Recipes!$A:$A,Consolidate!$B12) -> 0 | I12: =G12-H12 -> 316.52108 | K12: =SUMIF(Recipes!A:A,Consolidate!B12,Recipes!L:L) -> 339.44564 | L12: =SUMIFS(Recipes!$L:$L,Recipes!$D:$D,Consolidate!$E12,Recipes!$A:$A,Consolidate!$B12) -> 0 | M12: =K12-L12 -> 339.44564
A13: =A12+1 -> 11 | B13: Aloo Tarkari | C13: =VLOOKUP(B13,Recipes!A:B,2,0) -> Side Dish | D13: =VLOOKUP(B13,Recipes!A:C,3,0) -> Gravy | E13: =VLOOKUP(B13,Recipes!A:J,10,0) -> 0 | F13: =VLOOKUP(B13,Recipes!A:I,9,0) -> Kg | G13: =SUMIF(Recipes!A:A,Consolidate!B13,Recipes!H:H) -> 446.08222 | H13: =SUMIFS(Recipes!$H:$H,Recipes!$D:$D,Consolidate!$E13,Recipes!$A:$A,Consolidate!$B13) -> 0 | I13: =G13-H13 -> 446.08222 | K13: =SUMIF(Recipes!A:A,Consolidate!B13,Recipes!L:L) -> 590.0094 | L13: =SUMIFS(Recipes!$L:$L,Recipes!$D:$D,Consolidate!$E13,Recipes!$A:$A,Consolidate!$B13) -> 0 | M13: =K13-L13 -> 590.0094
A14: =A13+1 -> 12 | B14: Anda Chana | C14: =VLOOKUP(B14,Recipes!A:B,2,0) -> Side Dish | D14: =VLOOKUP(B14,Recipes!A:C,3,0) -> Daal / Chana | E14: =VLOOKUP(B14,Recipes!A:J,10,0) -> 0 | F14: =VLOOKUP(B14,Recipes!A:I,9,0) -> 20 Eggs | G14: =SUMIF(Recipes!A:A,Consolidate!B14,Recipes!H:H) -> 2424.3863 | H14: =SUMIFS(Recipes!$H:$H,Recipes!$D:$D,Consolidate!$E14,Recipes!$A:$A,Consolidate!$B14) -> 0 | I14: =G14-H14 -> 2424.3863 | K14: =SUMIF(Recipes!A:A,Consolidate!B14,Recipes!L:L) -> 2319.29 | L14: =SUMIFS(Recipes!$L:$L,Recipes!$D:$D,Consolidate!$E14,Recipes!$A:$A,Consolidate!$B14) -> 0 | M14: =K14-L14 -> 2319.29
A15: =A14+1 -> 13 | B15: Anda Cut | C15: =VLOOKUP(B15,Recipes!A:B,2,0) -> Side Dish | D15: =VLOOKUP(B15,Recipes!A:C,3,0) -> Gravy | E15: =VLOOKUP(B15,Recipes!A:J,10,0) -> 0 | F15: =VLOOKUP(B15,Recipes!A:I,9,0) -> 6 Eggs | G15: =SUMIF(Recipes!A:A,Consolidate!B15,Recipes!H:H) -> 266.04 | H15: =SUMIFS(Recipes!$H:$H,Recipes!$D:$D,Consolidate!$E15,Recipes!$A:$A,Consolidate!$B15) -> 0 | I15: =G15-H15 -> 266.04 | K15: =SUMIF(Recipes!A:A,Consolidate!B15,Recipes!L:L) -> 246.03 | L15: =SUMIFS(Recipes!$L:$L,Recipes!$D:$D,Consolidate!$E15,Recipes!$A:$A,Consolidate!$B15) -> 0 | M15: =K15-L15 -> 246.03
... A415: =A414+1 -> 413 | B415: Mini Samosa | C415: =VLOOKUP(B415,Recipes!A:B,2,0) -> Appetizer | D415: =VLOOKUP(B415,Recipes!A:C,3,0) -> Without Meat | E415: =VLOOKUP(B415,Recipes!A:J,10,0) -> 0 | F415: =VLOOKUP(B415,Recipes!A:I,9,0) -> Pcs | G415: =SUMIF(Recipes!A:A,Consolidate!B415,Recipes!H:H) -> 16.30082 | H415: =SUMIFS(Recipes!$H:$H,Recipes!$D:$D,Consolidate!$E415,Recipes!$A:$A,Consolidate!$B415) -> 0 | I415: =G415-H415 -> 16.30082 | K415: =SUMIF(Recipes!A:A,Consolidate!B415,Recipes!L:L) -> 16.552187 | L415: =SUMIFS(Recipes!$L:$L,Recipes!$D:$D,Consolidate!$E415,Recipes!$A:$A,Consolidate!$B415) -> 0 | M415: =K415-L415 -> 16.552187

Sheet Average Rates
C1: BBQ | D1: SITE
A2: Dish Category | B2: Dish Type | C2: Average Rates | D2: Average Rates
A4: Appetizer | B4: With Meat | C4: =AVERAGEIFS(Consolidate!G:G,Consolidate!D:D,'Average Rates'!B4,Consolidate!C:C,'Average Rates'!A4) -> 22.658851 | D4: =AVERAGEIFS(Consolidate!K:K,Consolidate!D:D,'Average Rates'!B4,Consolidate!C:C,'Average Rates'!A4) -> 23.102548
A5: Appetizer | B5: Without Meat | C5: =AVERAGEIFS(Consolidate!G:G,Consolidate!D:D,'Average Rates'!B5,Consolidate!C:C,'Average Rates'!A5) -> 20.2734 | D5: =AVERAGEIFS(Consolidate!K:K,Consolidate!D:D,'Average Rates'!B5,Consolidate!C:C,'Average Rates'!A5) -> 18.83354
A6: Appetizer | B6: French Fries | C6: =AVERAGEIFS(Consolidate!G:G,Consolidate!D:D,'Average Rates'!B6,Consolidate!C:C,'Average Rates'!A6) -> 169.426 | D6: =AVERAGEIFS(Consolidate!K:K,Consolidate!D:D,'Average Rates'!B6,Consolidate!C:C,'Average Rates'!A6) -> 190.55
A7: Appetizer | B7: Cracker | C7: =AVERAGEIFS(Consolidate!G:G,Consolidate!D:D,'Average Rates'!B7,Consolidate!C:C,'Average Rates'!A7) -> 491.336 | D7: =AVERAGEIFS(Consolidate!K:K,Consolidate!D:D,'Average Rates'!B7,Consolidate!C:C,'Average Rates'!A7) -> 497
A8: Beverages | B8: Cold Drink | C8: =AVERAGEIFS(Consolidate!G:G,Consolidate!D:D,'Average Rates'!B8,Consolidate!C:C,'Average Rates'!A8) -> 50 | D8: =AVERAGEIFS(Consolidate!K:K,Consolidate!D:D,'Average Rates'!B8,Consolidate!C:C,'Average Rates'!A8) -> 50
A9: Beverages | B9: Cold Drink Tin | C9: =AVERAGEIFS(Consolidate!G:G,Consolidate!D:D,'Average Rates'!B9,Consolidate!C:C,'Average Rates'!A9) -> 66 | D9: =AVERAGEIFS(Consolidate!K:K,Consolidate!D:D,'Average Rates'!B9,Consolidate!C:C,'Average Rates'!A9) -> 66
A10: Beverages | B10: Detox Drink | C10: =AVERAGEIFS(Consolidate!G:G,Consolidate!D:D,'Average Rates'!B10,Consolidate!C:C,'Average Rates'!A10) -> 10 | D10: =AVERAGEIFS(Consolidate!K:K,Consolidate!D:D,'Average Rates'!B10,Consolidate!C:C,'Average Rates'!A10) -> 10
A11: Beverages | B11: Fresh Juice | C11: =AVERAGEIFS(Consolidate!G:G,Consolidate!D:D,'Average Rates'!B11,Consolidate!C:C,'Average Rates'!A11) -> 57.19475 | D11: =AVERAGEIFS(Consolidate!K:K,Consolidate!D:D,'Average Rates'!B11,Consolidate!C:C,'Average Rates'!A11) -> 46.686714
A12: Beverages | B12: Hot Beverage | C12: =AVERAGEIFS(Consolidate!G:G,Consolidate!D:D,'Average Rates'!B12,Consolidate!C:C,'Average Rates'!A12) -> 94.51575 | D12: =AVERAGEIFS(Consolidate!K:K,Consolidate!D:D,'Average Rates'!B12,Consolidate!C:C,'Average Rates'!A12) -> 64.36075
A13: Beverages | B13: Lassi | C13: =AVERAGEIFS(Consolidate!G:G,Consolidate!D:D,'Average Rates'!B13,Consolidate!C:C,'Average Rates'!A13) -> 540.525 | D13: =AVERAGEIFS(Consolidate!K:K,Consolidate!D:D,'Average Rates'!B13,Consolidate!C:C,'Average Rates'!A13) -> 649.15
A14: Beverages | B14: Nestle Juice 1 Ltr | C14: =AVERAGEIFS(Consolidate!G:G,Consolidate!D:D,'Average Rates'!B14,Consolidate!C:C,'Average Rates'!A14) -> 260 | D14: =AVERAGEIFS(Consolidate!K:K,Consolidate!D:D,'Average Rates'!B14,Consolidate!C:C,'Average Rates'!A14) -> 260
A15: Beverages | B15: Nestle Juice 250ml | C15: =AVERAGEIFS(Consolidate!G:G,Consolidate!D:D,'Average Rates'!B15,Consolidate!C:C,'Average Rates'!A15) -> 45 | D15: =AVERAGEIFS(Consolidate!K:K,Consolidate!D:D,'Average Rates'!B15,Consolidate!C:C,'Average Rates'!A15) -> 45
... A31: Dessert | B31: Kulfi | C31: =AVERAGEIFS(Consolidate!G:G,Consolidate!D:D,'Average Rates'!B31,Consolidate!C:C,'Average Rates'!A31) -> 70 | D31: =AVERAGEIFS(Consolidate!K:K,Consolidate!D:D,'Average Rates'!B31,Consolidate!C:C,'Average Rates'!A31) -> 70
A32: Beef Cube | B32: Gravy | C32: =AVERAGEIFS(Consolidate!G:G,Consolidate!E:E,'Average Rates'!A32,Consolidate!D:D,'Average Rates'!B32) -> 1138.3294 | D32: =AVERAGEIFS(Consolidate!K:K,Consolidate!D:D,'Average Rates'!B32,Consolidate!E:E,'Average Rates'!A32) -> 1292.2419
A33: Beef Cube | B33: Rice | C33: =AVERAGEIFS(Consolidate!G:G,Consolidate!E:E,'Average Rates'!A33,Consolidate!D:D,'Average Rates'!B33) -> 1437.3646 | D33: =AVERAGEIFS(Consolidate!K:K,Consolidate!D:D,'Average Rates'!B33,Consolidate!E:E,'Average Rates'!A33) -> 1562.5789
A34: Beef Boneless | B34: BBQ | C34: =AVERAGEIFS(Consolidate!G:G,Consolidate!E:E,'Average Rates'!A34,Consolidate!D:D,'Average Rates'!B34) -> 1363.9629 | D34: =AVERAGEIFS(Consolidate!K:K,Consolidate!D:D,'Average Rates'!B34,Consolidate!E:E,'Average Rates'!A34) -> 1343.1938
A35: Beef Boneless | B35: Dry | C35: =AVERAGEIFS(Consolidate!G:G,Consolidate!E:E,'Average Rates'!A35,Consolidate!D:D,'Average Rates'!B35) -> 684.51703 | D35: =AVERAGEIFS(Consolidate!K:K,Consolidate!D:D,'Average Rates'!B35,Consolidate!E:E,'Average Rates'!A35) -> 639.34238
A36: Beef Boneless | B36: Fried | C36: =AVERAGEIFS(Consolidate!G:G,Consolidate!E:E,'Average Rates'!A36,Consolidate!D:D,'Average Rates'!B36) -> 1285.5287 | D36: =AVERAGEIFS(Consolidate!K:K,Consolidate!D:D,'Average Rates'!B36,Consolidate!E:E,'Average Rates'!A36) -> 1321.3245
A37: Beef Boneless | B37: Gravy | C37: =AVERAGEIFS(Consolidate!G:G,Consolidate!E:E,'Average Rates'!A37,Consolidate!D:D,'Average Rates'!B37) -> 1413.506 | D37: =AVERAGEIFS(Consolidate!K:K,Consolidate!D:D,'Average Rates'!B37,Consolidate!E:E,'Average Rates'!A37) -> 1384.1587
A38: Beef Boneless | B38: Grilled | C38: =AVERAGEIFS(Consolidate!G:G,Consolidate!E:E,'Average Rates'!A38,Consolidate!D:D,'Average Rates'!B38) -> 1342.7236 | D38: =AVERAGEIFS(Consolidate!K:K,Consolidate!D:D,'Average Rates'!B38,Consolidate!E:E,'Average Rates'!A38) -> 1267.9983
A39: Chicken Bone In | B39: BBQ | C39: =AVERAGEIFS(Consolidate!G:G,Consolidate!E:E,'Average Rates'!A39,Consolidate!D:D,'Average Rates'!B39) -> 852.66322 | D39: =AVERAGEIFS(Consolidate!K:K,Consolidate!D:D,'Average Rates'!B39,Consolidate!E:E,'Average Rates'!A39) -> 958.47891
A40: Chicken Bone In | B40: Dry | C40: =AVERAGEIFS(Consolidate!G:G,Consolidate!E:E,'Average Rates'!A40,Consolidate!D:D,'Average Rates'!B40) -> 790.2614 | D40: =AVERAGEIFS(Consolidate!K:K,Consolidate!D:D,'Average Rates'!B40,Consolidate!E:E,'Average Rates'!A40) -> 844.915
A41: Chicken Bone In | B41: Fried | C41: =AVERAGEIFS(Consolidate!G:G,Consolidate!E:E,'Average Rates'!A41,Consolidate!D:D,'Average Rates'!B41) -> 846.93306 | D41: =AVERAGEIFS(Consolidate!K:K,Consolidate!D:D,'Average Rates'!B41,Consolidate!E:E,'Average Rates'!A41) -> 1034.6894
A42: Chicken Bone In | B42: Gravy | C42: =AVERAGEIFS(Consolidate!G:G,Consolidate!E:E,'Average Rates'!A42,Consolidate!D:D,'Average Rates'!B42) -> 996.10139 | D42: =AVERAGEIFS(Consolidate!K:K,Consolidate!D:D,'Average Rates'!B42,Consolidate!E:E,'Average Rates'!A42) -> 1087.9274
A43: Chicken Bone In | B43: Grilled | C43: =AVERAGEIFS(Consolidate!G:G,Consolidate!E:E,'Average Rates'!A43,Consolidate!D:D,'Average Rates'!B43) -> 915.68591 | D43: =AVERAGEIFS(Consolidate!K:K,Consolidate!D:D,'Average Rates'!B43,Consolidate!E:E,'Average Rates'!A43) -> 978.63605
... A67: Prawn | B67: Rice | C67: =AVERAGEIFS(Consolidate!G:G,Consolidate!E:E,'Average Rates'!A67,Consolidate!D:D,'Average Rates'!B67) -> 2500.5406 | D67: =AVERAGEIFS(Consolidate!K:K,Consolidate!D:D,'Average Rates'!B67,Consolidate!E:E,'Average Rates'!A67) -> 2062.805
A68: Roti & Paratha | B68: Aloo Paratha | C68: =AVERAGEIFS(Consolidate!G:G,Consolidate!D:D,'Average Rates'!B68,Consolidate!C:C,'Average Rates'!A68) -> 34.18817 | D68: =AVERAGEIFS(Consolidate!K:K,Consolidate!D:D,'Average Rates'!B68,Consolidate!C:C,'Average Rates'!A68) -> 36.1815
A69: Roti & Paratha | B69: Bread White | C69: =AVERAGEIFS(Consolidate!G:G,Consolidate!D:D,'Average Rates'!B69,Consolidate!C:C,'Average Rates'!A69) -> 10.135625 | D69: =AVERAGEIFS(Consolidate!K:K,Consolidate!D:D,'Average Rates'!B69,Consolidate!C:C,'Average Rates'!A69) -> 9.8933333
A70: Roti & Paratha | B70: Chapati | C70: =AVERAGEIFS(Consolidate!G:G,Consolidate!D:D,'Average Rates'!B70,Consolidate!C:C,'Average Rates'!A70) -> 8.5139678 | D70: =AVERAGEIFS(Consolidate!K:K,Consolidate!D:D,'Average Rates'!B70,Consolidate!C:C,'Average Rates'!A70) -> 8.5437558
A71: Roti & Paratha | B71: Garlic Bread | C71: =AVERAGEIFS(Consolidate!G:G,Consolidate!D:D,'Average Rates'!B71,Consolidate!C:C,'Average Rates'!A71) -> 10.405625 | D71: =AVERAGEIFS(Consolidate!K:K,Consolidate!D:D,'Average Rates'!B71,Consolidate!C:C,'Average Rates'!A71) -> 10.203333
A72: Roti & Paratha | B72: Kachori | C72: =AVERAGEIFS(Consolidate!G:G,Consolidate!D:D,'Average Rates'!B72,Consolidate!C:C,'Average Rates'!A72) -> 13.60386 | D72: =AVERAGEIFS(Consolidate!K:K,Consolidate!D:D,'Average Rates'!B72,Consolidate!C:C,'Average Rates'!A72) -> 13.867148
A73: Roti & Paratha | B73: Naan | C73: =AVERAGEIFS(Consolidate!G:G,Consolidate!D:D,'Average Rates'!B73,Consolidate!C:C,'Average Rates'!A73) -> 37.928873 | D73: =AVERAGEIFS(Consolidate!K:K,Consolidate!D:D,'Average Rates'!B73,Consolidate!C:C,'Average Rates'!A73) -> 38.239584
A74: Roti & Paratha | B74: Paratha | C74: =AVERAGEIFS(Consolidate!G:G,Consolidate!D:D,'Average Rates'!B74,Consolidate!C:C,'Average Rates'!A74) -> 21.774938 | D74: =AVERAGEIFS(Consolidate!K:K,Consolidate!D:D,'Average Rates'!B74,Consolidate!C:C,'Average Rates'!A74) -> 22.630895
A75: Roti & Paratha | B75: Puri | C75: =AVERAGEIFS(Consolidate!G:G,Consolidate!D:D,'Average Rates'!B75,Consolidate!C:C,'Average Rates'!A75) -> 18.64423 | D75: =AVERAGEIFS(Consolidate!K:K,Consolidate!D:D,'Average Rates'!B75,Consolidate!C:C,'Average Rates'!A75) -> 19.172
A76: Chicken Boneless | B76: Chicken Paratha | C76: =AVERAGEIFS(Consolidate!G:G,Consolidate!E:E,'Average Rates'!A76,Consolidate!D:D,'Average Rates'!B76) -> 171.41508 | D76: =AVERAGEIFS(Consolidate!K:K,Consolidate!D:D,'Average Rates'!B76,Consolidate!E:E,'Average Rates'!A76) -> 185.33343
A77: Salad | B77: Chaat | C77: =AVERAGEIFS(Consolidate!G:G,Consolidate!D:D,'Average Rates'!B77,Consolidate!C:C,'Average Rates'!A77) -> 31.208 | D77: =AVERAGEIFS(Consolidate!K:K,Consolidate!D:D,'Average Rates'!B77,Consolidate!C:C,'Average Rates'!A77) -> 39.599969
A78: Salad | B78: With Meat | C78: =AVERAGEIFS(Consolidate!G:G,Consolidate!D:D,'Average Rates'!B78,Consolidate!C:C,'Average Rates'!A78) -> 1846.4765 | D78: =AVERAGEIFS(Consolidate!K:K,Consolidate!D:D,'Average Rates'!B78,Consolidate!C:C,'Average Rates'!A78) -> 1464.114
A79: Salad | B79: Without Meat | C79: =AVERAGEIFS(Consolidate!G:G,Consolidate!D:D,'Average Rates'!B79,Consolidate!C:C,'Average Rates'!A79) -> 793.46762 | D79: =AVERAGEIFS(Consolidate!K:K,Consolidate!D:D,'Average Rates'!B79,Consolidate!C:C,'Average Rates'!A79) -> 603.21794
...

Sheet Category Wise
A1: Category Wise Summary
A2: Dish Category | B2: Dish Type | C2: No Of Count
A3: Appetizer | B3: With Meat | C3: =COUNTIFS(Consolidate!C:C,'Category Wise'!A3,Consolidate!D:D,'Category Wise'!B3) -> 6
A4: Appetizer | B4: Without Meat | C4: =COUNTIFS(Consolidate!C:C,'Category Wise'!A4,Consolidate!D:D,'Category Wise'!B4) -> 5
A5: Beverages | B5: Beverages | C5: =COUNTIFS(Consolidate!C:C,'Category Wise'!A5,Consolidate!D:D,'Category Wise'!B5) -> 0
A6: Beverages | B6: Fresh Juice | C6: =COUNTIFS(Consolidate!C:C,'Category Wise'!A6,Consolidate!D:D,'Category Wise'!B6) -> 4
A7: Beverages | B7: Juice | C7: =COUNTIFS(Consolidate!C:C,'Category Wise'!A7,Consolidate!D:D,'Category Wise'!B7) -> 0
A8: Beverages | B8: Lassi | C8: =COUNTIFS(Consolidate!C:C,'Category Wise'!A8,Consolidate!D:D,'Category Wise'!B8) -> 2
A9: Beverages | B9: Tea | C9: =COUNTIFS(Consolidate!C:C,'Category Wise'!A9,Consolidate!D:D,'Category Wise'!B9) -> 0
A10: Chatni & Sauces | B10: Chatni & Sauces | C10: =COUNTIFS(Consolidate!C:C,'Category Wise'!A10,Consolidate!D:D,'Category Wise'!B10) -> 11
A11: Dessert | B11: Bakery | C11: =COUNTIFS(Consolidate!C:C,'Category Wise'!A11,Consolidate!D:D,'Category Wise'!B11) -> 9
A12: Dessert | B12: Dessert | C12: =COUNTIFS(Consolidate!C:C,'Category Wise'!A12,Consolidate!D:D,'Category Wise'!B12) -> 22
A13: Dessert | B13: Dry | C13: =COUNTIFS(Consolidate!C:C,'Category Wise'!A13,Consolidate!D:D,'Category Wise'!B13) -> 6
A14: Dessert | B14: Halwa | C14: =COUNTIFS(Consolidate!C:C,'Category Wise'!A14,Consolidate!D:D,'Category Wise'!B14) -> 0
... A34: Soup | B34: Without Meat | C34: =COUNTIFS(Consolidate!C:C,'Category Wise'!A34,Consolidate!D:D,'Category Wise'!B34) -> 1
B36: Total Dishes | C36: =SUM(C3:C35) -> 337

Sheet Ingredients
E1: 45161 | F1: 45192
A2: S. # | B2: Ingredients | C2: Site Items | D2: Review Frequency | E2: Rates | G2: Site Rates
A3: 15 | B3: Tullo Oil 16 Ltr | C3: COOKING OIL 16LTR | E3: 8500 | F3: =E3/16 -> 531.25 | G3: 550
A4: 163 | B4: Banaspati Ghee 16 Kg | C4: COOKING OIL 16LTR | E4: 8500 | F4: =E4/16 -> 531.25 | G4: 8800 | H4: =G4/16 -> 550
A5: 214 | B5: Bisco Ghee 16kg | C5: COOKING OIL 16LTR | E5: 8500 | F5: =E5/16 -> 531.25 | G5: 8800 | H5: =G5/16 -> 550
A6: 38 | B6: Javetri | C6: MACE (JAWETRI) | E6: 6500 | G6: 6500
A7: 141 | B7: Pista | C7: PISTACHIO | E7: 6500 | G7: 6200
A8: 43 | B8: Olive Oil Mundial | C8: OLIVE OIL | E8: 5432.77 | G8: 3200
A9: 140 | B9: Cardamom (s) Kg | C9: CARDAMOM GREEN | E9: 5000 | G9: 3200
A10: 296 | C10: Sun Dried Tomatoes | E10: 4500 | G10: 4500
A11: 174 | B11: Cardamom (l) Kg | C11: CARDAMOM BLACK | E11: 4000 | G11: 2900
A12: 138 | B12: Chocolate Essence Bottle | C12: Chocolate Essence Bottle | E12: 3690 | G12: 4000
A13: 165 | B13: Long Seed | C13: CLOVE | E13: 3600 | G13: 3400
A14: 189 | B14: Kajo Kg | C14: CASHEW NUT (KAJU) | E14: 3000 | G14: 2900
A15: 175 | B15: Seekh Kabab Masala | C15: TIKKA MASALA KG | E15: 2848.84 | G15: 2643.68
A16: 212 | B16: Nescafe 220gm Coffee | C16: COFFEE 200GM | E16: 1920 | F16: =E16/0.2 -> 9600 | G16: 9600
A17: 28 | B17: Zeera Seeds | C17: CUMIN SEED WHITE | E17: 2400 | G17: 1600
A18: 87 | B18: White Paper Powder Kg | C18: WHITE PEPPER PWD | E18: 2300 | G18: 2150
A19: 192 | B19: Dagi Mirch Powder Kg | C19: RED CHILLI PWD KG | E19: 2200 | G19: 1500
A20: 193 | B20: Black Zeera | C20: BLACK ZEERA | E20: 2200 | G20: 1400
A21: 54 | B21: White Paper Seed | C21: WHITE PEPPER PWD | E21: 2100 | G21: 2150
A22: 130 | B22: CREAM CHEESE BOX | C22: CREAM CHEESE BOX | E22: 2100 | G22: 2100
A23: 36 | B23: Hot Spice Powder. | C23: GARAM MASALA | E23: 2000 | G23: 1900
A24: 96 | B24: Almond (badam) | C24: ALMOND | E24: 2000 | G24: 2080
A25: 228 | B25: Walnut (akhrot) | C25: Walnut (akhrot) | E25: 2000 | G25: 2400
A26: 243 | B26: Mutton Boneless Cut | C26: MUTTON BONELESS | E26: 1958 | G26: 2200
A27: 85 | B27: Mutton Boneless | C27: MUTTON BONELESS | E27: 1957.5 | G27: 2200
A28: 33 | B28: Jaifal Seed | C28: NUTMEG WHOLE (JAIFAL) | E28: 1900 | G28: 1900
... A58: 220 | B58: Rabri | C58: Rabri | E58: 1900 | G58: 1900
A59: 77 | B59: Cheese Slice 1kg | C59: CHEESE SLICE 800GM | E59: 1296 | F59: =E59/0.8 -> 1620 | G59: 1296
A60: 124 | B60: Milk Powder Kg | C60: EVERYDAY MILK PWD 2KG | E60: 1260 | G60: 1280
A61: 50 | B61: Chadder Cheese | C61: CHEESE CHEDDAR 2KG | E61: 1224.07 | F61: =E61/2 -> 612.035 | G61: 1224.73
A62: 259 | B62: Biryani Essence | C62: Biryani Essence | E62: 1200 | G62: 1200
A63: 217 | B63: Sonf Seed | C63: ANISE SEED | E63: 1150 | G63: 1100
A64: 65 | B64: Chicken Powder Kg | C64: CHICKEN PWD 1000GM | E64: 1113.51 | G64: 1066.33
A65: 76 | B65: Chili Sauce 5 Ltr | C65: CHILLI SAUCE 750ML | E65: 1100 | G65: 1100
A66: 216 | B66: Sount (Sukha adrak kg | C66: Sount (Sukha adrak kg | E66: 1100 | G66: 1100
A67: 224 | B67: Rasgulla | C67: Rasgulla | E67: 1100 | G67: 1100
A68: 231 | B68: Mutton Paya | C68: MUTTON PAYA | E68: 1100 | G68: 480
A69: 284 | B69: Cham Cham | C69: CHAM CHAM | E69: 1100 | G69: 1100
...
